<?xml version="1.0" ?>
<!-- =================================================================================== -->
<!-- |    This document was autogenerated by xacro from pexod.xacro                    | -->
<!-- |    EDITING THIS FILE BY HAND IS NOT RECOMMENDED                                 | -->
<!-- =================================================================================== -->
<robot name="pexod" xmlns:xacro="http://www.ros.org/wiki/xacro">
  <!-- <xacro:include filename="$(find pexod_description)/urdf/pexod_control.xacro" /> -->
  <!-- MATERIALS -->
  <material name="Blue">
    <color rgba="0 0 1 1"/>
  </material>
  <material name="Red">
    <color rgba="1 0 0 1"/>
  </material>
  <material name="Green">
    <color rgba="0 1 0 1"/>
  </material>
  <material name="Yellow">
    <color rgba="1 1 0 1"/>
  </material>
  <material name="LightGrey">
    <color rgba="0.6 0.6 0.6 1.0"/>
  </material>
  <!-- END OF MATERIALS -->
  <!-- XACRO MACROS FOR VISUALS AND COLLISIONS -->
  <!-- END OF XACRO MACROS -->
  <!-- TORSO -->
  <link name="base_link">
    <visual>
      <origin rpy="0 0 0" xyz="0 0 0"/>
      <geometry>
        <box size="0.24 0.2 0.04"/>
      </geometry>
      <material name="Blue"/>
    </visual>
    <collision>
      <origin rpy="0 0 0" xyz="0 0 0"/>
      <geometry>
        <box size="0.24 0.2 0.04"/>
      </geometry>
    </collision>
    <inertial>
      <!-- CENTER OF MASS -->
      <origin rpy="0 0 0" xyz="0 0 0"/>
      <mass value="1.031"/>
      <!-- box inertia: 1/12*m(y^2+z^2), ... -->
      <inertia ixx="0.00357413333333" ixy="0" ixz="0" iyy="0.00508626666667" iyz="0" izz="0.00838546666667"/>
    </inertial>
  </link>
  <!-- XACRO MACRO FOR LEGS LINKS/JOINTS -->
  <!-- END OF LEG LINKS/JOINTS -->
  <joint name="body_leg_2" type="revolute">
    <parent link="base_link"/>
    <child link="leg_2_1"/>
    <limit effort="30.0" lower="-1.57079632679" upper="1.57079632679" velocity="7.0"/>
    <origin rpy="0 0 -0.3" xyz="0.11 0.04 0"/>
    <!-- <xacro:if value="${index == 5 or index == 4 or index == 3}">
                <axis xyz="0 0 1"/>
            </xacro:if>
            <xacro:if value="${index == 2 or index == 1 or index == 0}"> -->
    <axis xyz="0 0 1"/>
    <!-- </xacro:if> -->
    <dynamics damping="0.0"/>
  </joint>
  <link name="leg_2_1">
    <visual>
      <origin rpy="1.57079632679 0 0" xyz="0.01 0.03 0"/>
      <geometry>
        <cylinder length="0.06" radius="0.02"/>
      </geometry>
      <material name="Red"/>
    </visual>
    <collision>
      <origin rpy="1.57079632679 0 0" xyz="0.01 0.03 0"/>
      <geometry>
        <box size="0.02 0.02 0.06"/>
      </geometry>
    </collision>
    <inertial>
      <!-- CENTER OF MASS -->
      <origin rpy="1.57079632679 0 0" xyz="0.01 0.03 0"/>
      <mass value="0.02"/>
      <!-- box inertia: 1/12*m(y^2+z^2), ... -->
      <inertia ixx="6.66666666667e-06" ixy="0" ixz="0" iyy="6.66666666667e-06" iyz="0" izz="1.33333333333e-06"/>
    </inertial>
  </link>
  <joint name="leg_2_1_2" type="revolute">
    <parent link="leg_2_1"/>
    <child link="leg_2_2"/>
    <limit effort="30.0" lower="-0.78539816339" upper="0.78539816339" velocity="7.0"/>
    <origin rpy="0 0 0" xyz="0 0.06 0"/>
    <axis xyz="1 0 0"/>
    <dynamics damping="0.0"/>
  </joint>
  <link name="leg_2_2">
    <visual>
      <origin rpy="1.57079632679 0 0" xyz="0.01 0.0401463164873 0"/>
      <geometry>
        <cylinder length="0.0802926329746" radius="0.02"/>
      </geometry>
      <material name="Blue"/>
    </visual>
    <collision>
      <origin rpy="1.57079632679 0 0" xyz="0.01 0.0401463164873 0"/>
      <geometry>
        <box size="0.02 0.02 0.0802926329746"/>
      </geometry>
    </collision>
    <inertial>
      <!-- CENTER OF MASS -->
      <origin rpy="1.57079632679 0 0" xyz="0.01 0.0401463164873 0"/>
      <mass value="0.184"/>
      <!-- box inertia: 1/12*m(y^2+z^2), ... -->
      <inertia ixx="0.000104985905953" ixy="0" ixz="0" iyy="0.000104985905953" iyz="0" izz="1.22666666667e-05"/>
    </inertial>
  </link>
  <joint name="leg_2_2_3" type="revolute">
    <parent link="leg_2_2"/>
    <child link="leg_2_3"/>
    <limit effort="30.0" lower="-0.78539816339" upper="0.78539816339" velocity="7.0"/>
    <origin rpy="-1.57079632679 0 0" xyz="0 0.0802926329746 0"/>
    <axis xyz="-1 0 0"/>
    <dynamics damping="0.0"/>
  </joint>
  <link name="leg_2_3">
    <visual>
      <origin rpy="1.57079632679 0 0" xyz="0.0125 0.0712399577235 0"/>
      <geometry>
        <cylinder length="0.142479915447" radius="0.025"/>
      </geometry>
      <material name="Red"/>
    </visual>
    <visual>
      <origin rpy="1.57079632679 0 0" xyz="0.0125 0.129979915447 0"/>
      <geometry>
        <sphere radius="0.025"/>
      </geometry>
      <material name="Red"/>
    </visual>
    <collision>
      <origin rpy="1.57079632679 0 0" xyz="0.0125 0.0712399577235 0"/>
      <geometry>
        <box size="0.025 0.025 0.142479915447"/>
      </geometry>
    </collision>
    <collision>
      <origin rpy="1.57079632679 0 0" xyz="0.0125 0.129979915447 0"/>
      <geometry>
        <sphere radius="0.025"/>
      </geometry>
      <material name="Red"/>
    </collision>
    <inertial>
      <!-- CENTER OF MASS -->
      <origin rpy="1.57079632679 0 0" xyz="0.0125 0.0712399577235 0"/>
      <mass value="0.04"/>
      <!-- box inertia: 1/12*m(y^2+z^2), ... -->
      <inertia ixx="6.97517543526e-05" ixy="0" ixz="0" iyy="6.97517543526e-05" iyz="0" izz="4.16666666667e-06"/>
    </inertial>
  </link>
  <joint name="body_leg_3" type="revolute">
    <parent link="base_link"/>
    <child link="leg_3_1"/>
    <limit effort="30.0" lower="-1.57079632679" upper="1.57079632679" velocity="7.0"/>
    <origin rpy="0 0 0.3" xyz="0.11 -0.04 0"/>
    <!-- <xacro:if value="${index == 5 or index == 4 or index == 3}">
                <axis xyz="0 0 1"/>
            </xacro:if>
            <xacro:if value="${index == 2 or index == 1 or index == 0}"> -->
    <axis xyz="0 0 1"/>
    <!-- </xacro:if> -->
    <dynamics damping="0.0"/>
  </joint>
  <link name="leg_3_1">
    <visual>
      <origin rpy="1.57079632679 0 0" xyz="0.01 -0.03 0"/>
      <geometry>
        <cylinder length="0.06" radius="0.02"/>
      </geometry>
      <material name="Red"/>
    </visual>
    <collision>
      <origin rpy="1.57079632679 0 0" xyz="0.01 -0.03 0"/>
      <geometry>
        <box size="0.02 0.02 0.06"/>
      </geometry>
    </collision>
    <inertial>
      <!-- CENTER OF MASS -->
      <origin rpy="1.57079632679 0 0" xyz="0.01 -0.03 0"/>
      <mass value="0.02"/>
      <!-- box inertia: 1/12*m(y^2+z^2), ... -->
      <inertia ixx="6.66666666667e-06" ixy="0" ixz="0" iyy="6.66666666667e-06" iyz="0" izz="1.33333333333e-06"/>
    </inertial>
  </link>
  <joint name="leg_3_1_2" type="revolute">
    <parent link="leg_3_1"/>
    <child link="leg_3_2"/>
    <limit effort="30.0" lower="-0.78539816339" upper="0.78539816339" velocity="7.0"/>
    <origin rpy="0 0 0" xyz="0 -0.06 0"/>
    <axis xyz="-1 0 0"/>
    <dynamics damping="0.0"/>
  </joint>
  <link name="leg_3_2">
    <visual>
      <origin rpy="1.57079632679 0 0" xyz="0.01 -0.0497235626142 0"/>
      <geometry>
        <cylinder length="0.0994471252283" radius="0.02"/>
      </geometry>
      <material name="Blue"/>
    </visual>
    <collision>
      <origin rpy="1.57079632679 0 0" xyz="0.01 -0.0497235626142 0"/>
      <geometry>
        <box size="0.02 0.02 0.0994471252283"/>
      </geometry>
    </collision>
    <inertial>
      <!-- CENTER OF MASS -->
      <origin rpy="1.57079632679 0 0" xyz="0.01 -0.0497235626142 0"/>
      <mass value="0.184"/>
      <!-- box inertia: 1/12*m(y^2+z^2), ... -->
      <inertia ixx="0.000157775870981" ixy="0" ixz="0" iyy="0.000157775870981" iyz="0" izz="1.22666666667e-05"/>
    </inertial>
  </link>
  <joint name="leg_3_2_3" type="revolute">
    <parent link="leg_3_2"/>
    <child link="leg_3_3"/>
    <limit effort="30.0" lower="-0.78539816339" upper="0.78539816339" velocity="7.0"/>
    <origin rpy="1.57079632679 0 0" xyz="0 -0.0994471252283 0"/>
    <axis xyz="1 0 0"/>
    <dynamics damping="0.0"/>
  </joint>
  <link name="leg_3_3">
    <visual>
      <origin rpy="1.57079632679 0 0" xyz="0.0125 -0.076765636361 0"/>
      <geometry>
        <cylinder length="0.153531272722" radius="0.025"/>
      </geometry>
      <material name="Red"/>
    </visual>
    <visual>
      <origin rpy="1.57079632679 0 0" xyz="0.0125 -0.141031272722 0"/>
      <geometry>
        <sphere radius="0.025"/>
      </geometry>
      <material name="Red"/>
    </visual>
    <collision>
      <origin rpy="1.57079632679 0 0" xyz="0.0125 -0.076765636361 0"/>
      <geometry>
        <box size="0.025 0.025 0.153531272722"/>
      </geometry>
    </collision>
    <collision>
      <origin rpy="1.57079632679 0 0" xyz="0.0125 -0.141031272722 0"/>
      <geometry>
        <sphere radius="0.025"/>
      </geometry>
      <material name="Red"/>
    </collision>
    <inertial>
      <!-- CENTER OF MASS -->
      <origin rpy="1.57079632679 0 0" xyz="0.0125 -0.076765636361 0"/>
      <mass value="0.04"/>
      <!-- box inertia: 1/12*m(y^2+z^2), ... -->
      <inertia ixx="8.06561723455e-05" ixy="0" ixz="0" iyy="8.06561723455e-05" iyz="0" izz="4.16666666667e-06"/>
    </inertial>
  </link>
  <joint name="body_leg_0" type="revolute">
    <parent link="base_link"/>
    <child link="leg_0_1"/>
    <limit effort="30.0" lower="-1.57079632679" upper="1.57079632679" velocity="7.0"/>
    <origin rpy="0 0 0.3" xyz="-0.13 0.04 0"/>
    <!-- <xacro:if value="${index == 5 or index == 4 or index == 3}">
                <axis xyz="0 0 1"/>
            </xacro:if>
            <xacro:if value="${index == 2 or index == 1 or index == 0}"> -->
    <axis xyz="0 0 1"/>
    <!-- </xacro:if> -->
    <dynamics damping="0.0"/>
  </joint>
  <link name="leg_0_1">
    <visual>
      <origin rpy="1.57079632679 0 0" xyz="0.01 0.03 0"/>
      <geometry>
        <cylinder length="0.06" radius="0.02"/>
      </geometry>
      <material name="Red"/>
    </visual>
    <collision>
      <origin rpy="1.57079632679 0 0" xyz="0.01 0.03 0"/>
      <geometry>
        <box size="0.02 0.02 0.06"/>
      </geometry>
    </collision>
    <inertial>
      <!-- CENTER OF MASS -->
      <origin rpy="1.57079632679 0 0" xyz="0.01 0.03 0"/>
      <mass value="0.02"/>
      <!-- box inertia: 1/12*m(y^2+z^2), ... -->
      <inertia ixx="6.66666666667e-06" ixy="0" ixz="0" iyy="6.66666666667e-06" iyz="0" izz="1.33333333333e-06"/>
    </inertial>
  </link>
  <joint name="leg_0_1_2" type="revolute">
    <parent link="leg_0_1"/>
    <child link="leg_0_2"/>
    <limit effort="30.0" lower="-0.78539816339" upper="0.78539816339" velocity="7.0"/>
    <origin rpy="0 0 0" xyz="0 0.06 0"/>
    <axis xyz="1 0 0"/>
    <dynamics damping="0.0"/>
  </joint>
  <link name="leg_0_2">
    <visual>
      <origin rpy="1.57079632679 0 0" xyz="0.01 0.0379289952008 0"/>
      <geometry>
        <cylinder length="0.0758579904015" radius="0.02"/>
      </geometry>
      <material name="Blue"/>
    </visual>
    <collision>
      <origin rpy="1.57079632679 0 0" xyz="0.01 0.0379289952008 0"/>
      <geometry>
        <box size="0.02 0.02 0.0758579904015"/>
      </geometry>
    </collision>
    <inertial>
      <!-- CENTER OF MASS -->
      <origin rpy="1.57079632679 0 0" xyz="0.01 0.0379289952008 0"/>
      <mass value="0.184"/>
      <!-- box inertia: 1/12*m(y^2+z^2), ... -->
      <inertia ixx="9.43679988522e-05" ixy="0" ixz="0" iyy="9.43679988522e-05" iyz="0" izz="1.22666666667e-05"/>
    </inertial>
  </link>
  <joint name="leg_0_2_3" type="revolute">
    <parent link="leg_0_2"/>
    <child link="leg_0_3"/>
    <limit effort="30.0" lower="-0.78539816339" upper="0.78539816339" velocity="7.0"/>
    <origin rpy="-1.57079632679 0 0" xyz="0 0.0758579904015 0"/>
    <axis xyz="-1 0 0"/>
    <dynamics damping="0.0"/>
  </joint>
  <link name="leg_0_3">
    <visual>
      <origin rpy="1.57079632679 0 0" xyz="0.0125 0.065521655073 0"/>
      <geometry>
        <cylinder length="0.131043310146" radius="0.025"/>
      </geometry>
      <material name="Red"/>
    </visual>
    <visual>
      <origin rpy="1.57079632679 0 0" xyz="0.0125 0.118543310146 0"/>
      <geometry>
        <sphere radius="0.025"/>
      </geometry>
      <material name="Red"/>
    </visual>
    <collision>
      <origin rpy="1.57079632679 0 0" xyz="0.0125 0.065521655073 0"/>
      <geometry>
        <box size="0.025 0.025 0.131043310146"/>
      </geometry>
    </collision>
    <collision>
      <origin rpy="1.57079632679 0 0" xyz="0.0125 0.118543310146 0"/>
      <geometry>
        <sphere radius="0.025"/>
      </geometry>
      <material name="Red"/>
    </collision>
    <inertial>
      <!-- CENTER OF MASS -->
      <origin rpy="1.57079632679 0 0" xyz="0.0125 0.065521655073 0"/>
      <mass value="0.04"/>
      <!-- box inertia: 1/12*m(y^2+z^2), ... -->
      <inertia ixx="5.93244971134e-05" ixy="0" ixz="0" iyy="5.93244971134e-05" iyz="0" izz="4.16666666667e-06"/>
    </inertial>
  </link>
  <joint name="body_leg_5" type="revolute">
    <parent link="base_link"/>
    <child link="leg_5_1"/>
    <limit effort="30.0" lower="-1.57079632679" upper="1.57079632679" velocity="7.0"/>
    <origin rpy="0 0 -0.3" xyz="-0.13 -0.04 0"/>
    <!-- <xacro:if value="${index == 5 or index == 4 or index == 3}">
                <axis xyz="0 0 1"/>
            </xacro:if>
            <xacro:if value="${index == 2 or index == 1 or index == 0}"> -->
    <axis xyz="0 0 1"/>
    <!-- </xacro:if> -->
    <dynamics damping="0.0"/>
  </joint>
  <link name="leg_5_1">
    <visual>
      <origin rpy="1.57079632679 0 0" xyz="0.01 -0.03 0"/>
      <geometry>
        <cylinder length="0.06" radius="0.02"/>
      </geometry>
      <material name="Red"/>
    </visual>
    <collision>
      <origin rpy="1.57079632679 0 0" xyz="0.01 -0.03 0"/>
      <geometry>
        <box size="0.02 0.02 0.06"/>
      </geometry>
    </collision>
    <inertial>
      <!-- CENTER OF MASS -->
      <origin rpy="1.57079632679 0 0" xyz="0.01 -0.03 0"/>
      <mass value="0.02"/>
      <!-- box inertia: 1/12*m(y^2+z^2), ... -->
      <inertia ixx="6.66666666667e-06" ixy="0" ixz="0" iyy="6.66666666667e-06" iyz="0" izz="1.33333333333e-06"/>
    </inertial>
  </link>
  <joint name="leg_5_1_2" type="revolute">
    <parent link="leg_5_1"/>
    <child link="leg_5_2"/>
    <limit effort="30.0" lower="-0.78539816339" upper="0.78539816339" velocity="7.0"/>
    <origin rpy="0 0 0" xyz="0 -0.06 0"/>
    <axis xyz="-1 0 0"/>
    <dynamics damping="0.0"/>
  </joint>
  <link name="leg_5_2">
    <visual>
      <origin rpy="1.57079632679 0 0" xyz="0.01 -0.0427635729114 0"/>
      <geometry>
        <cylinder length="0.0855271458229" radius="0.02"/>
      </geometry>
      <material name="Blue"/>
    </visual>
    <collision>
      <origin rpy="1.57079632679 0 0" xyz="0.01 -0.0427635729114 0"/>
      <geometry>
        <box size="0.02 0.02 0.0855271458229"/>
      </geometry>
    </collision>
    <inertial>
      <!-- CENTER OF MASS -->
      <origin rpy="1.57079632679 0 0" xyz="0.01 -0.0427635729114 0"/>
      <mass value="0.184"/>
      <!-- box inertia: 1/12*m(y^2+z^2), ... -->
      <inertia ixx="0.00011829502098" ixy="0" ixz="0" iyy="0.00011829502098" iyz="0" izz="1.22666666667e-05"/>
    </inertial>
  </link>
  <joint name="leg_5_2_3" type="revolute">
    <parent link="leg_5_2"/>
    <child link="leg_5_3"/>
    <limit effort="30.0" lower="-0.78539816339" upper="0.78539816339" velocity="7.0"/>
    <origin rpy="1.57079632679 0 0" xyz="0 -0.0855271458229 0"/>
    <axis xyz="1 0 0"/>
    <dynamics damping="0.0"/>
  </joint>
  <link name="leg_5_3">
    <visual>
      <origin rpy="1.57079632679 0 0" xyz="0.0125 -0.070249707011 0"/>
      <geometry>
        <cylinder length="0.140499414022" radius="0.025"/>
      </geometry>
      <material name="Red"/>
    </visual>
    <visual>
      <origin rpy="1.57079632679 0 0" xyz="0.0125 -0.127999414022 0"/>
      <geometry>
        <sphere radius="0.025"/>
      </geometry>
      <material name="Red"/>
    </visual>
    <collision>
      <origin rpy="1.57079632679 0 0" xyz="0.0125 -0.070249707011 0"/>
      <geometry>
        <box size="0.025 0.025 0.140499414022"/>
      </geometry>
    </collision>
    <collision>
      <origin rpy="1.57079632679 0 0" xyz="0.0125 -0.127999414022 0"/>
      <geometry>
        <sphere radius="0.025"/>
      </geometry>
      <material name="Red"/>
    </collision>
    <inertial>
      <!-- CENTER OF MASS -->
      <origin rpy="1.57079632679 0 0" xyz="0.0125 -0.070249707011 0"/>
      <mass value="0.04"/>
      <!-- box inertia: 1/12*m(y^2+z^2), ... -->
      <inertia ixx="6.78836178018e-05" ixy="0" ixz="0" iyy="6.78836178018e-05" iyz="0" izz="4.16666666667e-06"/>
    </inertial>
  </link>
  <joint name="body_leg_1" type="revolute">
    <parent link="base_link"/>
    <child link="leg_1_1"/>
    <limit effort="30.0" lower="-1.57079632679" upper="1.57079632679" velocity="7.0"/>
    <origin rpy="0 0 0" xyz="-0.01 0.08 0"/>
    <!-- <xacro:if value="${index == 5 or index == 4 or index == 3}">
                <axis xyz="0 0 1"/>
            </xacro:if>
            <xacro:if value="${index == 2 or index == 1 or index == 0}"> -->
    <axis xyz="0 0 1"/>
    <!-- </xacro:if> -->
    <dynamics damping="0.0"/>
  </joint>
  <link name="leg_1_1">
    <visual>
      <origin rpy="1.57079632679 0 0" xyz="0.01 0.03 0"/>
      <geometry>
        <cylinder length="0.06" radius="0.02"/>
      </geometry>
      <material name="Red"/>
    </visual>
    <collision>
      <origin rpy="1.57079632679 0 0" xyz="0.01 0.03 0"/>
      <geometry>
        <box size="0.02 0.02 0.06"/>
      </geometry>
    </collision>
    <inertial>
      <!-- CENTER OF MASS -->
      <origin rpy="1.57079632679 0 0" xyz="0.01 0.03 0"/>
      <mass value="0.02"/>
      <!-- box inertia: 1/12*m(y^2+z^2), ... -->
      <inertia ixx="6.66666666667e-06" ixy="0" ixz="0" iyy="6.66666666667e-06" iyz="0" izz="1.33333333333e-06"/>
    </inertial>
  </link>
  <joint name="leg_1_1_2" type="revolute">
    <parent link="leg_1_1"/>
    <child link="leg_1_2"/>
    <limit effort="30.0" lower="-0.78539816339" upper="0.78539816339" velocity="7.0"/>
    <origin rpy="0 0 0" xyz="0 0.06 0"/>
    <axis xyz="1 0 0"/>
    <dynamics damping="0.0"/>
  </joint>
  <link name="leg_1_2">
    <visual>
      <origin rpy="1.57079632679 0 0" xyz="0.01 0.0490188229576 0"/>
      <geometry>
        <cylinder length="0.0980376459151" radius="0.02"/>
      </geometry>
      <material name="Blue"/>
    </visual>
    <collision>
      <origin rpy="1.57079632679 0 0" xyz="0.01 0.0490188229576 0"/>
      <geometry>
        <box size="0.02 0.02 0.0980376459151"/>
      </geometry>
    </collision>
    <inertial>
      <!-- CENTER OF MASS -->
      <origin rpy="1.57079632679 0 0" xyz="0.01 0.0490188229576 0"/>
      <mass value="0.184"/>
      <!-- box inertia: 1/12*m(y^2+z^2), ... -->
      <inertia ixx="0.000153507826921" ixy="0" ixz="0" iyy="0.000153507826921" iyz="0" izz="1.22666666667e-05"/>
    </inertial>
  </link>
  <joint name="leg_1_2_3" type="revolute">
    <parent link="leg_1_2"/>
    <child link="leg_1_3"/>
    <limit effort="30.0" lower="-0.78539816339" upper="0.78539816339" velocity="7.0"/>
    <origin rpy="-1.57079632679 0 0" xyz="0 0.0980376459151 0"/>
    <axis xyz="-1 0 0"/>
    <dynamics damping="0.0"/>
  </joint>
  <link name="leg_1_3">
    <visual>
      <origin rpy="1.57079632679 0 0" xyz="0.0125 0.062699072433 0"/>
      <geometry>
        <cylinder length="0.125398144866" radius="0.025"/>
      </geometry>
      <material name="Red"/>
    </visual>
    <visual>
      <origin rpy="1.57079632679 0 0" xyz="0.0125 0.112898144866 0"/>
      <geometry>
        <sphere radius="0.025"/>
      </geometry>
      <material name="Red"/>
    </visual>
    <collision>
      <origin rpy="1.57079632679 0 0" xyz="0.0125 0.062699072433 0"/>
      <geometry>
        <box size="0.025 0.025 0.125398144866"/>
      </geometry>
    </collision>
    <collision>
      <origin rpy="1.57079632679 0 0" xyz="0.0125 0.112898144866 0"/>
      <geometry>
        <sphere radius="0.025"/>
      </geometry>
      <material name="Red"/>
    </collision>
    <inertial>
      <!-- CENTER OF MASS -->
      <origin rpy="1.57079632679 0 0" xyz="0.0125 0.062699072433 0"/>
      <mass value="0.04"/>
      <!-- box inertia: 1/12*m(y^2+z^2), ... -->
      <inertia ixx="5.44989824528e-05" ixy="0" ixz="0" iyy="5.44989824528e-05" iyz="0" izz="4.16666666667e-06"/>
    </inertial>
  </link>
  <joint name="body_leg_4" type="revolute">
    <parent link="base_link"/>
    <child link="leg_4_1"/>
    <limit effort="30.0" lower="-1.57079632679" upper="1.57079632679" velocity="7.0"/>
    <origin rpy="0 0 0" xyz="-0.01 -0.08 0"/>
    <!-- <xacro:if value="${index == 5 or index == 4 or index == 3}">
                <axis xyz="0 0 1"/>
            </xacro:if>
            <xacro:if value="${index == 2 or index == 1 or index == 0}"> -->
    <axis xyz="0 0 1"/>
    <!-- </xacro:if> -->
    <dynamics damping="0.0"/>
  </joint>
  <link name="leg_4_1">
    <visual>
      <origin rpy="1.57079632679 0 0" xyz="0.01 -0.03 0"/>
      <geometry>
        <cylinder length="0.06" radius="0.02"/>
      </geometry>
      <material name="Red"/>
    </visual>
    <collision>
      <origin rpy="1.57079632679 0 0" xyz="0.01 -0.03 0"/>
      <geometry>
        <box size="0.02 0.02 0.06"/>
      </geometry>
    </collision>
    <inertial>
      <!-- CENTER OF MASS -->
      <origin rpy="1.57079632679 0 0" xyz="0.01 -0.03 0"/>
      <mass value="0.02"/>
      <!-- box inertia: 1/12*m(y^2+z^2), ... -->
      <inertia ixx="6.66666666667e-06" ixy="0" ixz="0" iyy="6.66666666667e-06" iyz="0" izz="1.33333333333e-06"/>
    </inertial>
  </link>
  <joint name="leg_4_1_2" type="revolute">
    <parent link="leg_4_1"/>
    <child link="leg_4_2"/>
    <limit effort="30.0" lower="-0.78539816339" upper="0.78539816339" velocity="7.0"/>
    <origin rpy="0 0 0" xyz="0 -0.06 0"/>
    <axis xyz="-1 0 0"/>
    <dynamics damping="0.0"/>
  </joint>
  <link name="leg_4_2">
    <visual>
      <origin rpy="1.57079632679 0 0" xyz="0.01 -0.036471218928 0"/>
      <geometry>
        <cylinder length="0.0729424378561" radius="0.02"/>
      </geometry>
      <material name="Blue"/>
    </visual>
    <collision>
      <origin rpy="1.57079632679 0 0" xyz="0.01 -0.036471218928 0"/>
      <geometry>
        <box size="0.02 0.02 0.0729424378561"/>
      </geometry>
    </collision>
    <inertial>
      <!-- CENTER OF MASS -->
      <origin rpy="1.57079632679 0 0" xyz="0.01 -0.036471218928 0"/>
      <mass value="0.184"/>
      <!-- box inertia: 1/12*m(y^2+z^2), ... -->
      <inertia ixx="8.77158550193e-05" ixy="0" ixz="0" iyy="8.77158550193e-05" iyz="0" izz="1.22666666667e-05"/>
    </inertial>
  </link>
  <joint name="leg_4_2_3" type="revolute">
    <parent link="leg_4_2"/>
    <child link="leg_4_3"/>
    <limit effort="30.0" lower="-0.78539816339" upper="0.78539816339" velocity="7.0"/>
    <origin rpy="1.57079632679 0 0" xyz="0 -0.0729424378561 0"/>
    <axis xyz="1 0 0"/>
    <dynamics damping="0.0"/>
  </joint>
  <link name="leg_4_3">
    <visual>
      <origin rpy="1.57079632679 0 0" xyz="0.0125 -0.0697203957685 0"/>
      <geometry>
        <cylinder length="0.139440791537" radius="0.025"/>
      </geometry>
      <material name="Red"/>
    </visual>
    <visual>
      <origin rpy="1.57079632679 0 0" xyz="0.0125 -0.126940791537 0"/>
      <geometry>
        <sphere radius="0.025"/>
      </geometry>
      <material name="Red"/>
    </visual>
    <collision>
      <origin rpy="1.57079632679 0 0" xyz="0.0125 -0.0697203957685 0"/>
      <geometry>
        <box size="0.025 0.025 0.139440791537"/>
      </geometry>
    </collision>
    <collision>
      <origin rpy="1.57079632679 0 0" xyz="0.0125 -0.126940791537 0"/>
      <geometry>
        <sphere radius="0.025"/>
      </geometry>
      <material name="Red"/>
    </collision>
    <inertial>
      <!-- CENTER OF MASS -->
      <origin rpy="1.57079632679 0 0" xyz="0.0125 -0.0697203957685 0"/>
      <mass value="0.04"/>
      <!-- box inertia: 1/12*m(y^2+z^2), ... -->
      <inertia ixx="6.68957811482e-05" ixy="0" ixz="0" iyy="6.68957811482e-05" iyz="0" izz="4.16666666667e-06"/>
    </inertial>
  </link>
  <!-- END OF LEG LINKS/JOINTS -->
</robot>
