<?xml version="1.0" ?>
<!-- =================================================================================== -->
<!-- |    This document was autogenerated by xacro from pexod.xacro                    | -->
<!-- |    EDITING THIS FILE BY HAND IS NOT RECOMMENDED                                 | -->
<!-- =================================================================================== -->
<robot name="pexod" xmlns:xacro="http://www.ros.org/wiki/xacro">
  <!-- <xacro:include filename="$(find pexod_description)/urdf/pexod_control.xacro" /> -->
  <!-- MATERIALS -->
  <material name="Blue">
    <color rgba="0 0 1 1"/>
  </material>
  <material name="Red">
    <color rgba="1 0 0 1"/>
  </material>
  <material name="Green">
    <color rgba="0 1 0 1"/>
  </material>
  <material name="Yellow">
    <color rgba="1 1 0 1"/>
  </material>
  <material name="LightGrey">
    <color rgba="0.6 0.6 0.6 1.0"/>
  </material>
  <!-- END OF MATERIALS -->
  <!-- XACRO MACROS FOR VISUALS AND COLLISIONS -->
  <!-- END OF XACRO MACROS -->
  <!-- TORSO -->
  <link name="base_link">
    <visual>
      <origin rpy="0 0 0" xyz="0 0 0"/>
      <geometry>
        <box size="0.24 0.2 0.04"/>
      </geometry>
      <material name="Blue"/>
    </visual>
    <collision>
      <origin rpy="0 0 0" xyz="0 0 0"/>
      <geometry>
        <box size="0.24 0.2 0.04"/>
      </geometry>
    </collision>
    <inertial>
      <!-- CENTER OF MASS -->
      <origin rpy="0 0 0" xyz="0 0 0"/>
      <mass value="1.031"/>
      <!-- box inertia: 1/12*m(y^2+z^2), ... -->
      <inertia ixx="0.00357413333333" ixy="0" ixz="0" iyy="0.00508626666667" iyz="0" izz="0.00838546666667"/>
    </inertial>
  </link>
  <!-- XACRO MACRO FOR LEGS LINKS/JOINTS -->
  <!-- END OF LEG LINKS/JOINTS -->
  <joint name="body_leg_2" type="revolute">
    <parent link="base_link"/>
    <child link="leg_2_1"/>
    <limit effort="30.0" lower="-1.57079632679" upper="1.57079632679" velocity="7.0"/>
    <origin rpy="0 0 -0.3" xyz="0.11 0.04 0"/>
    <!-- <xacro:if value="${index == 5 or index == 4 or index == 3}">
                <axis xyz="0 0 1"/>
            </xacro:if>
            <xacro:if value="${index == 2 or index == 1 or index == 0}"> -->
    <axis xyz="0 0 1"/>
    <!-- </xacro:if> -->
    <dynamics damping="0.0"/>
  </joint>
  <link name="leg_2_1">
    <visual>
      <origin rpy="1.57079632679 0 0" xyz="0.01 0.03 0"/>
      <geometry>
        <cylinder length="0.06" radius="0.02"/>
      </geometry>
      <material name="Red"/>
    </visual>
    <collision>
      <origin rpy="1.57079632679 0 0" xyz="0.01 0.03 0"/>
      <geometry>
        <box size="0.02 0.02 0.06"/>
      </geometry>
    </collision>
    <inertial>
      <!-- CENTER OF MASS -->
      <origin rpy="1.57079632679 0 0" xyz="0.01 0.03 0"/>
      <mass value="0.02"/>
      <!-- box inertia: 1/12*m(y^2+z^2), ... -->
      <inertia ixx="6.66666666667e-06" ixy="0" ixz="0" iyy="6.66666666667e-06" iyz="0" izz="1.33333333333e-06"/>
    </inertial>
  </link>
  <joint name="leg_2_1_2" type="revolute">
    <parent link="leg_2_1"/>
    <child link="leg_2_2"/>
    <limit effort="30.0" lower="-0.78539816339" upper="0.78539816339" velocity="7.0"/>
    <origin rpy="0 0 0" xyz="0 0.06 0"/>
    <axis xyz="1 0 0"/>
    <dynamics damping="0.0"/>
  </joint>
  <link name="leg_2_2">
    <visual>
      <origin rpy="1.57079632679 0 0" xyz="0.01 0.053906732787 0"/>
      <geometry>
        <cylinder length="0.107813465574" radius="0.02"/>
      </geometry>
      <material name="Blue"/>
    </visual>
    <collision>
      <origin rpy="1.57079632679 0 0" xyz="0.01 0.053906732787 0"/>
      <geometry>
        <box size="0.02 0.02 0.107813465574"/>
      </geometry>
    </collision>
    <inertial>
      <!-- CENTER OF MASS -->
      <origin rpy="1.57079632679 0 0" xyz="0.01 0.053906732787 0"/>
      <mass value="0.184"/>
      <!-- box inertia: 1/12*m(y^2+z^2), ... -->
      <inertia ixx="0.000184364064839" ixy="0" ixz="0" iyy="0.000184364064839" iyz="0" izz="1.22666666667e-05"/>
    </inertial>
  </link>
  <joint name="leg_2_2_3" type="revolute">
    <parent link="leg_2_2"/>
    <child link="leg_2_3"/>
    <limit effort="30.0" lower="-0.78539816339" upper="0.78539816339" velocity="7.0"/>
    <origin rpy="-1.57079632679 0 0" xyz="0 0.107813465574 0"/>
    <axis xyz="-1 0 0"/>
    <dynamics damping="0.0"/>
  </joint>
  <link name="leg_2_3">
    <visual>
      <origin rpy="1.57079632679 0 0" xyz="0.0125 0.0834302559555 0"/>
      <geometry>
        <cylinder length="0.166860511911" radius="0.025"/>
      </geometry>
      <material name="Red"/>
    </visual>
    <visual>
      <origin rpy="1.57079632679 0 0" xyz="0.0125 0.154360511911 0"/>
      <geometry>
        <sphere radius="0.025"/>
      </geometry>
      <material name="Red"/>
    </visual>
    <collision>
      <origin rpy="1.57079632679 0 0" xyz="0.0125 0.0834302559555 0"/>
      <geometry>
        <box size="0.025 0.025 0.166860511911"/>
      </geometry>
    </collision>
    <collision>
      <origin rpy="1.57079632679 0 0" xyz="0.0125 0.154360511911 0"/>
      <geometry>
        <sphere radius="0.025"/>
      </geometry>
      <material name="Red"/>
    </collision>
    <inertial>
      <!-- CENTER OF MASS -->
      <origin rpy="1.57079632679 0 0" xyz="0.0125 0.0834302559555 0"/>
      <mass value="0.04"/>
      <!-- box inertia: 1/12*m(y^2+z^2), ... -->
      <inertia ixx="9.4891434784e-05" ixy="0" ixz="0" iyy="9.4891434784e-05" iyz="0" izz="4.16666666667e-06"/>
    </inertial>
  </link>
  <joint name="body_leg_3" type="revolute">
    <parent link="base_link"/>
    <child link="leg_3_1"/>
    <limit effort="30.0" lower="-1.57079632679" upper="1.57079632679" velocity="7.0"/>
    <origin rpy="0 0 0.3" xyz="0.11 -0.04 0"/>
    <!-- <xacro:if value="${index == 5 or index == 4 or index == 3}">
                <axis xyz="0 0 1"/>
            </xacro:if>
            <xacro:if value="${index == 2 or index == 1 or index == 0}"> -->
    <axis xyz="0 0 1"/>
    <!-- </xacro:if> -->
    <dynamics damping="0.0"/>
  </joint>
  <link name="leg_3_1">
    <visual>
      <origin rpy="1.57079632679 0 0" xyz="0.01 -0.03 0"/>
      <geometry>
        <cylinder length="0.06" radius="0.02"/>
      </geometry>
      <material name="Red"/>
    </visual>
    <collision>
      <origin rpy="1.57079632679 0 0" xyz="0.01 -0.03 0"/>
      <geometry>
        <box size="0.02 0.02 0.06"/>
      </geometry>
    </collision>
    <inertial>
      <!-- CENTER OF MASS -->
      <origin rpy="1.57079632679 0 0" xyz="0.01 -0.03 0"/>
      <mass value="0.02"/>
      <!-- box inertia: 1/12*m(y^2+z^2), ... -->
      <inertia ixx="6.66666666667e-06" ixy="0" ixz="0" iyy="6.66666666667e-06" iyz="0" izz="1.33333333333e-06"/>
    </inertial>
  </link>
  <joint name="leg_3_1_2" type="revolute">
    <parent link="leg_3_1"/>
    <child link="leg_3_2"/>
    <limit effort="30.0" lower="-0.78539816339" upper="0.78539816339" velocity="7.0"/>
    <origin rpy="0 0 0" xyz="0 -0.06 0"/>
    <axis xyz="-1 0 0"/>
    <dynamics damping="0.0"/>
  </joint>
  <link name="leg_3_2">
    <visual>
      <origin rpy="1.57079632679 0 0" xyz="0.01 -0.0319805400055 0"/>
      <geometry>
        <cylinder length="0.0639610800109" radius="0.02"/>
      </geometry>
      <material name="Blue"/>
    </visual>
    <collision>
      <origin rpy="1.57079632679 0 0" xyz="0.01 -0.0319805400055 0"/>
      <geometry>
        <box size="0.02 0.02 0.0639610800109"/>
      </geometry>
    </collision>
    <inertial>
      <!-- CENTER OF MASS -->
      <origin rpy="1.57079632679 0 0" xyz="0.01 -0.0319805400055 0"/>
      <mass value="0.184"/>
      <!-- box inertia: 1/12*m(y^2+z^2), ... -->
      <inertia ixx="6.88623029278e-05" ixy="0" ixz="0" iyy="6.88623029278e-05" iyz="0" izz="1.22666666667e-05"/>
    </inertial>
  </link>
  <joint name="leg_3_2_3" type="revolute">
    <parent link="leg_3_2"/>
    <child link="leg_3_3"/>
    <limit effort="30.0" lower="-0.78539816339" upper="0.78539816339" velocity="7.0"/>
    <origin rpy="1.57079632679 0 0" xyz="0 -0.0639610800109 0"/>
    <axis xyz="1 0 0"/>
    <dynamics damping="0.0"/>
  </joint>
  <link name="leg_3_3">
    <visual>
      <origin rpy="1.57079632679 0 0" xyz="0.0125 -0.0812217985 0"/>
      <geometry>
        <cylinder length="0.162443597" radius="0.025"/>
      </geometry>
      <material name="Red"/>
    </visual>
    <visual>
      <origin rpy="1.57079632679 0 0" xyz="0.0125 -0.149943597 0"/>
      <geometry>
        <sphere radius="0.025"/>
      </geometry>
      <material name="Red"/>
    </visual>
    <collision>
      <origin rpy="1.57079632679 0 0" xyz="0.0125 -0.0812217985 0"/>
      <geometry>
        <box size="0.025 0.025 0.162443597"/>
      </geometry>
    </collision>
    <collision>
      <origin rpy="1.57079632679 0 0" xyz="0.0125 -0.149943597 0"/>
      <geometry>
        <sphere radius="0.025"/>
      </geometry>
      <material name="Red"/>
    </collision>
    <inertial>
      <!-- CENTER OF MASS -->
      <origin rpy="1.57079632679 0 0" xyz="0.0125 -0.0812217985 0"/>
      <mass value="0.04"/>
      <!-- box inertia: 1/12*m(y^2+z^2), ... -->
      <inertia ixx="9.0043074021e-05" ixy="0" ixz="0" iyy="9.0043074021e-05" iyz="0" izz="4.16666666667e-06"/>
    </inertial>
  </link>
  <joint name="body_leg_0" type="revolute">
    <parent link="base_link"/>
    <child link="leg_0_1"/>
    <limit effort="30.0" lower="-1.57079632679" upper="1.57079632679" velocity="7.0"/>
    <origin rpy="0 0 0.3" xyz="-0.13 0.04 0"/>
    <!-- <xacro:if value="${index == 5 or index == 4 or index == 3}">
                <axis xyz="0 0 1"/>
            </xacro:if>
            <xacro:if value="${index == 2 or index == 1 or index == 0}"> -->
    <axis xyz="0 0 1"/>
    <!-- </xacro:if> -->
    <dynamics damping="0.0"/>
  </joint>
  <link name="leg_0_1">
    <visual>
      <origin rpy="1.57079632679 0 0" xyz="0.01 0.03 0"/>
      <geometry>
        <cylinder length="0.06" radius="0.02"/>
      </geometry>
      <material name="Red"/>
    </visual>
    <collision>
      <origin rpy="1.57079632679 0 0" xyz="0.01 0.03 0"/>
      <geometry>
        <box size="0.02 0.02 0.06"/>
      </geometry>
    </collision>
    <inertial>
      <!-- CENTER OF MASS -->
      <origin rpy="1.57079632679 0 0" xyz="0.01 0.03 0"/>
      <mass value="0.02"/>
      <!-- box inertia: 1/12*m(y^2+z^2), ... -->
      <inertia ixx="6.66666666667e-06" ixy="0" ixz="0" iyy="6.66666666667e-06" iyz="0" izz="1.33333333333e-06"/>
    </inertial>
  </link>
  <joint name="leg_0_1_2" type="revolute">
    <parent link="leg_0_1"/>
    <child link="leg_0_2"/>
    <limit effort="30.0" lower="-0.78539816339" upper="0.78539816339" velocity="7.0"/>
    <origin rpy="0 0 0" xyz="0 0.06 0"/>
    <axis xyz="1 0 0"/>
    <dynamics damping="0.0"/>
  </joint>
  <link name="leg_0_2">
    <visual>
      <origin rpy="1.57079632679 0 0" xyz="0.01 0.0257553398902 0"/>
      <geometry>
        <cylinder length="0.0515106797804" radius="0.02"/>
      </geometry>
      <material name="Blue"/>
    </visual>
    <collision>
      <origin rpy="1.57079632679 0 0" xyz="0.01 0.0257553398902 0"/>
      <geometry>
        <box size="0.02 0.02 0.0515106797804"/>
      </geometry>
    </collision>
    <inertial>
      <!-- CENTER OF MASS -->
      <origin rpy="1.57079632679 0 0" xyz="0.01 0.0257553398902 0"/>
      <mass value="0.184"/>
      <!-- box inertia: 1/12*m(y^2+z^2), ... -->
      <inertia ixx="4.68180353487e-05" ixy="0" ixz="0" iyy="4.68180353487e-05" iyz="0" izz="1.22666666667e-05"/>
    </inertial>
  </link>
  <joint name="leg_0_2_3" type="revolute">
    <parent link="leg_0_2"/>
    <child link="leg_0_3"/>
    <limit effort="30.0" lower="-0.78539816339" upper="0.78539816339" velocity="7.0"/>
    <origin rpy="-1.57079632679 0 0" xyz="0 0.0515106797804 0"/>
    <axis xyz="-1 0 0"/>
    <dynamics damping="0.0"/>
  </joint>
  <link name="leg_0_3">
    <visual>
      <origin rpy="1.57079632679 0 0" xyz="0.0125 0.0800853193185 0"/>
      <geometry>
        <cylinder length="0.160170638637" radius="0.025"/>
      </geometry>
      <material name="Red"/>
    </visual>
    <visual>
      <origin rpy="1.57079632679 0 0" xyz="0.0125 0.147670638637 0"/>
      <geometry>
        <sphere radius="0.025"/>
      </geometry>
      <material name="Red"/>
    </visual>
    <collision>
      <origin rpy="1.57079632679 0 0" xyz="0.0125 0.0800853193185 0"/>
      <geometry>
        <box size="0.025 0.025 0.160170638637"/>
      </geometry>
    </collision>
    <collision>
      <origin rpy="1.57079632679 0 0" xyz="0.0125 0.147670638637 0"/>
      <geometry>
        <sphere radius="0.025"/>
      </geometry>
      <material name="Red"/>
    </collision>
    <inertial>
      <!-- CENTER OF MASS -->
      <origin rpy="1.57079632679 0 0" xyz="0.0125 0.0800853193185 0"/>
      <mass value="0.04"/>
      <!-- box inertia: 1/12*m(y^2+z^2), ... -->
      <inertia ixx="8.75987782713e-05" ixy="0" ixz="0" iyy="8.75987782713e-05" iyz="0" izz="4.16666666667e-06"/>
    </inertial>
  </link>
  <joint name="body_leg_5" type="revolute">
    <parent link="base_link"/>
    <child link="leg_5_1"/>
    <limit effort="30.0" lower="-1.57079632679" upper="1.57079632679" velocity="7.0"/>
    <origin rpy="0 0 -0.3" xyz="-0.13 -0.04 0"/>
    <!-- <xacro:if value="${index == 5 or index == 4 or index == 3}">
                <axis xyz="0 0 1"/>
            </xacro:if>
            <xacro:if value="${index == 2 or index == 1 or index == 0}"> -->
    <axis xyz="0 0 1"/>
    <!-- </xacro:if> -->
    <dynamics damping="0.0"/>
  </joint>
  <link name="leg_5_1">
    <visual>
      <origin rpy="1.57079632679 0 0" xyz="0.01 -0.03 0"/>
      <geometry>
        <cylinder length="0.06" radius="0.02"/>
      </geometry>
      <material name="Red"/>
    </visual>
    <collision>
      <origin rpy="1.57079632679 0 0" xyz="0.01 -0.03 0"/>
      <geometry>
        <box size="0.02 0.02 0.06"/>
      </geometry>
    </collision>
    <inertial>
      <!-- CENTER OF MASS -->
      <origin rpy="1.57079632679 0 0" xyz="0.01 -0.03 0"/>
      <mass value="0.02"/>
      <!-- box inertia: 1/12*m(y^2+z^2), ... -->
      <inertia ixx="6.66666666667e-06" ixy="0" ixz="0" iyy="6.66666666667e-06" iyz="0" izz="1.33333333333e-06"/>
    </inertial>
  </link>
  <joint name="leg_5_1_2" type="revolute">
    <parent link="leg_5_1"/>
    <child link="leg_5_2"/>
    <limit effort="30.0" lower="-0.78539816339" upper="0.78539816339" velocity="7.0"/>
    <origin rpy="0 0 0" xyz="0 -0.06 0"/>
    <axis xyz="-1 0 0"/>
    <dynamics damping="0.0"/>
  </joint>
  <link name="leg_5_2">
    <visual>
      <origin rpy="1.57079632679 0 0" xyz="0.01 -0.0333906466006 0"/>
      <geometry>
        <cylinder length="0.0667812932013" radius="0.02"/>
      </geometry>
      <material name="Blue"/>
    </visual>
    <collision>
      <origin rpy="1.57079632679 0 0" xyz="0.01 -0.0333906466006 0"/>
      <geometry>
        <box size="0.02 0.02 0.0667812932013"/>
      </geometry>
    </collision>
    <inertial>
      <!-- CENTER OF MASS -->
      <origin rpy="1.57079632679 0 0" xyz="0.01 -0.0333906466006 0"/>
      <mass value="0.184"/>
      <!-- box inertia: 1/12*m(y^2+z^2), ... -->
      <inertia ixx="7.45160305318e-05" ixy="0" ixz="0" iyy="7.45160305318e-05" iyz="0" izz="1.22666666667e-05"/>
    </inertial>
  </link>
  <joint name="leg_5_2_3" type="revolute">
    <parent link="leg_5_2"/>
    <child link="leg_5_3"/>
    <limit effort="30.0" lower="-0.78539816339" upper="0.78539816339" velocity="7.0"/>
    <origin rpy="1.57079632679 0 0" xyz="0 -0.0667812932013 0"/>
    <axis xyz="1 0 0"/>
    <dynamics damping="0.0"/>
  </joint>
  <link name="leg_5_3">
    <visual>
      <origin rpy="1.57079632679 0 0" xyz="0.0125 -0.05966506042 0"/>
      <geometry>
        <cylinder length="0.11933012084" radius="0.025"/>
      </geometry>
      <material name="Red"/>
    </visual>
    <visual>
      <origin rpy="1.57079632679 0 0" xyz="0.0125 -0.10683012084 0"/>
      <geometry>
        <sphere radius="0.025"/>
      </geometry>
      <material name="Red"/>
    </visual>
    <collision>
      <origin rpy="1.57079632679 0 0" xyz="0.0125 -0.05966506042 0"/>
      <geometry>
        <box size="0.025 0.025 0.11933012084"/>
      </geometry>
    </collision>
    <collision>
      <origin rpy="1.57079632679 0 0" xyz="0.0125 -0.10683012084 0"/>
      <geometry>
        <sphere radius="0.025"/>
      </geometry>
      <material name="Red"/>
    </collision>
    <inertial>
      <!-- CENTER OF MASS -->
      <origin rpy="1.57079632679 0 0" xyz="0.0125 -0.05966506042 0"/>
      <mass value="0.04"/>
      <!-- box inertia: 1/12*m(y^2+z^2), ... -->
      <inertia ixx="4.9548925799e-05" ixy="0" ixz="0" iyy="4.9548925799e-05" iyz="0" izz="4.16666666667e-06"/>
    </inertial>
  </link>
  <joint name="body_leg_1" type="revolute">
    <parent link="base_link"/>
    <child link="leg_1_1"/>
    <limit effort="30.0" lower="-1.57079632679" upper="1.57079632679" velocity="7.0"/>
    <origin rpy="0 0 0" xyz="-0.01 0.08 0"/>
    <!-- <xacro:if value="${index == 5 or index == 4 or index == 3}">
                <axis xyz="0 0 1"/>
            </xacro:if>
            <xacro:if value="${index == 2 or index == 1 or index == 0}"> -->
    <axis xyz="0 0 1"/>
    <!-- </xacro:if> -->
    <dynamics damping="0.0"/>
  </joint>
  <link name="leg_1_1">
    <visual>
      <origin rpy="1.57079632679 0 0" xyz="0.01 0.03 0"/>
      <geometry>
        <cylinder length="0.06" radius="0.02"/>
      </geometry>
      <material name="Red"/>
    </visual>
    <collision>
      <origin rpy="1.57079632679 0 0" xyz="0.01 0.03 0"/>
      <geometry>
        <box size="0.02 0.02 0.06"/>
      </geometry>
    </collision>
    <inertial>
      <!-- CENTER OF MASS -->
      <origin rpy="1.57079632679 0 0" xyz="0.01 0.03 0"/>
      <mass value="0.02"/>
      <!-- box inertia: 1/12*m(y^2+z^2), ... -->
      <inertia ixx="6.66666666667e-06" ixy="0" ixz="0" iyy="6.66666666667e-06" iyz="0" izz="1.33333333333e-06"/>
    </inertial>
  </link>
  <joint name="leg_1_1_2" type="revolute">
    <parent link="leg_1_1"/>
    <child link="leg_1_2"/>
    <limit effort="30.0" lower="-0.78539816339" upper="0.78539816339" velocity="7.0"/>
    <origin rpy="0 0 0" xyz="0 0.06 0"/>
    <axis xyz="1 0 0"/>
    <dynamics damping="0.0"/>
  </joint>
  <link name="leg_1_2">
    <visual>
      <origin rpy="1.57079632679 0 0" xyz="0.01 0.0449050070813 0"/>
      <geometry>
        <cylinder length="0.0898100141627" radius="0.02"/>
      </geometry>
      <material name="Blue"/>
    </visual>
    <collision>
      <origin rpy="1.57079632679 0 0" xyz="0.01 0.0449050070813 0"/>
      <geometry>
        <box size="0.02 0.02 0.0898100141627"/>
      </geometry>
    </collision>
    <inertial>
      <!-- CENTER OF MASS -->
      <origin rpy="1.57079632679 0 0" xyz="0.01 0.0449050070813 0"/>
      <mass value="0.184"/>
      <!-- box inertia: 1/12*m(y^2+z^2), ... -->
      <inertia ixx="0.000129809525873" ixy="0" ixz="0" iyy="0.000129809525873" iyz="0" izz="1.22666666667e-05"/>
    </inertial>
  </link>
  <joint name="leg_1_2_3" type="revolute">
    <parent link="leg_1_2"/>
    <child link="leg_1_3"/>
    <limit effort="30.0" lower="-0.78539816339" upper="0.78539816339" velocity="7.0"/>
    <origin rpy="-1.57079632679 0 0" xyz="0 0.0898100141627 0"/>
    <axis xyz="-1 0 0"/>
    <dynamics damping="0.0"/>
  </joint>
  <link name="leg_1_3">
    <visual>
      <origin rpy="1.57079632679 0 0" xyz="0.0125 0.0807813977225 0"/>
      <geometry>
        <cylinder length="0.161562795445" radius="0.025"/>
      </geometry>
      <material name="Red"/>
    </visual>
    <visual>
      <origin rpy="1.57079632679 0 0" xyz="0.0125 0.149062795445 0"/>
      <geometry>
        <sphere radius="0.025"/>
      </geometry>
      <material name="Red"/>
    </visual>
    <collision>
      <origin rpy="1.57079632679 0 0" xyz="0.0125 0.0807813977225 0"/>
      <geometry>
        <box size="0.025 0.025 0.161562795445"/>
      </geometry>
    </collision>
    <collision>
      <origin rpy="1.57079632679 0 0" xyz="0.0125 0.149062795445 0"/>
      <geometry>
        <sphere radius="0.025"/>
      </geometry>
      <material name="Red"/>
    </collision>
    <inertial>
      <!-- CENTER OF MASS -->
      <origin rpy="1.57079632679 0 0" xyz="0.0125 0.0807813977225 0"/>
      <mass value="0.04"/>
      <!-- box inertia: 1/12*m(y^2+z^2), ... -->
      <inertia ixx="8.90917895733e-05" ixy="0" ixz="0" iyy="8.90917895733e-05" iyz="0" izz="4.16666666667e-06"/>
    </inertial>
  </link>
  <joint name="body_leg_4" type="revolute">
    <parent link="base_link"/>
    <child link="leg_4_1"/>
    <limit effort="30.0" lower="-1.57079632679" upper="1.57079632679" velocity="7.0"/>
    <origin rpy="0 0 0" xyz="-0.01 -0.08 0"/>
    <!-- <xacro:if value="${index == 5 or index == 4 or index == 3}">
                <axis xyz="0 0 1"/>
            </xacro:if>
            <xacro:if value="${index == 2 or index == 1 or index == 0}"> -->
    <axis xyz="0 0 1"/>
    <!-- </xacro:if> -->
    <dynamics damping="0.0"/>
  </joint>
  <link name="leg_4_1">
    <visual>
      <origin rpy="1.57079632679 0 0" xyz="0.01 -0.03 0"/>
      <geometry>
        <cylinder length="0.06" radius="0.02"/>
      </geometry>
      <material name="Red"/>
    </visual>
    <collision>
      <origin rpy="1.57079632679 0 0" xyz="0.01 -0.03 0"/>
      <geometry>
        <box size="0.02 0.02 0.06"/>
      </geometry>
    </collision>
    <inertial>
      <!-- CENTER OF MASS -->
      <origin rpy="1.57079632679 0 0" xyz="0.01 -0.03 0"/>
      <mass value="0.02"/>
      <!-- box inertia: 1/12*m(y^2+z^2), ... -->
      <inertia ixx="6.66666666667e-06" ixy="0" ixz="0" iyy="6.66666666667e-06" iyz="0" izz="1.33333333333e-06"/>
    </inertial>
  </link>
  <joint name="leg_4_1_2" type="revolute">
    <parent link="leg_4_1"/>
    <child link="leg_4_2"/>
    <limit effort="30.0" lower="-0.78539816339" upper="0.78539816339" velocity="7.0"/>
    <origin rpy="0 0 0" xyz="0 -0.06 0"/>
    <axis xyz="-1 0 0"/>
    <dynamics damping="0.0"/>
  </joint>
  <link name="leg_4_2">
    <visual>
      <origin rpy="1.57079632679 0 0" xyz="0.01 -0.0318757044638 0"/>
      <geometry>
        <cylinder length="0.0637514089276" radius="0.02"/>
      </geometry>
      <material name="Blue"/>
    </visual>
    <collision>
      <origin rpy="1.57079632679 0 0" xyz="0.01 -0.0318757044638 0"/>
      <geometry>
        <box size="0.02 0.02 0.0637514089276"/>
      </geometry>
    </collision>
    <inertial>
      <!-- CENTER OF MASS -->
      <origin rpy="1.57079632679 0 0" xyz="0.01 -0.0318757044638 0"/>
      <mass value="0.184"/>
      <!-- box inertia: 1/12*m(y^2+z^2), ... -->
      <inertia ixx="6.84517128172e-05" ixy="0" ixz="0" iyy="6.84517128172e-05" iyz="0" izz="1.22666666667e-05"/>
    </inertial>
  </link>
  <joint name="leg_4_2_3" type="revolute">
    <parent link="leg_4_2"/>
    <child link="leg_4_3"/>
    <limit effort="30.0" lower="-0.78539816339" upper="0.78539816339" velocity="7.0"/>
    <origin rpy="1.57079632679 0 0" xyz="0 -0.0637514089276 0"/>
    <axis xyz="1 0 0"/>
    <dynamics damping="0.0"/>
  </joint>
  <link name="leg_4_3">
    <visual>
      <origin rpy="1.57079632679 0 0" xyz="0.0125 -0.088746141411 0"/>
      <geometry>
        <cylinder length="0.177492282822" radius="0.025"/>
      </geometry>
      <material name="Red"/>
    </visual>
    <visual>
      <origin rpy="1.57079632679 0 0" xyz="0.0125 -0.164992282822 0"/>
      <geometry>
        <sphere radius="0.025"/>
      </geometry>
      <material name="Red"/>
    </visual>
    <collision>
      <origin rpy="1.57079632679 0 0" xyz="0.0125 -0.088746141411 0"/>
      <geometry>
        <box size="0.025 0.025 0.177492282822"/>
      </geometry>
    </collision>
    <collision>
      <origin rpy="1.57079632679 0 0" xyz="0.0125 -0.164992282822 0"/>
      <geometry>
        <sphere radius="0.025"/>
      </geometry>
      <material name="Red"/>
    </collision>
    <inertial>
      <!-- CENTER OF MASS -->
      <origin rpy="1.57079632679 0 0" xyz="0.0125 -0.088746141411 0"/>
      <mass value="0.04"/>
      <!-- box inertia: 1/12*m(y^2+z^2), ... -->
      <inertia ixx="0.000107095034871" ixy="0" ixz="0" iyy="0.000107095034871" iyz="0" izz="4.16666666667e-06"/>
    </inertial>
  </link>
  <!-- END OF LEG LINKS/JOINTS -->
</robot>
