<?xml version="1.0" ?>
<!-- =================================================================================== -->
<!-- |    This document was autogenerated by xacro from pexod.xacro                    | -->
<!-- |    EDITING THIS FILE BY HAND IS NOT RECOMMENDED                                 | -->
<!-- =================================================================================== -->
<robot name="pexod" xmlns:xacro="http://www.ros.org/wiki/xacro">
  <!-- <xacro:include filename="$(find pexod_description)/urdf/pexod_control.xacro" /> -->
  <!-- MATERIALS -->
  <material name="Blue">
    <color rgba="0 0 1 1"/>
  </material>
  <material name="Red">
    <color rgba="1 0 0 1"/>
  </material>
  <material name="Green">
    <color rgba="0 1 0 1"/>
  </material>
  <material name="Yellow">
    <color rgba="1 1 0 1"/>
  </material>
  <material name="LightGrey">
    <color rgba="0.6 0.6 0.6 1.0"/>
  </material>
  <!-- END OF MATERIALS -->
  <!-- XACRO MACROS FOR VISUALS AND COLLISIONS -->
  <!-- END OF XACRO MACROS -->
  <!-- TORSO -->
  <link name="base_link">
    <visual>
      <origin rpy="0 0 0" xyz="0 0 0"/>
      <geometry>
        <box size="0.24 0.2 0.04"/>
      </geometry>
      <material name="Blue"/>
    </visual>
    <collision>
      <origin rpy="0 0 0" xyz="0 0 0"/>
      <geometry>
        <box size="0.24 0.2 0.04"/>
      </geometry>
    </collision>
    <inertial>
      <!-- CENTER OF MASS -->
      <origin rpy="0 0 0" xyz="0 0 0"/>
      <mass value="1.031"/>
      <!-- box inertia: 1/12*m(y^2+z^2), ... -->
      <inertia ixx="0.00357413333333" ixy="0" ixz="0" iyy="0.00508626666667" iyz="0" izz="0.00838546666667"/>
    </inertial>
  </link>
  <!-- XACRO MACRO FOR LEGS LINKS/JOINTS -->
  <!-- END OF LEG LINKS/JOINTS -->
  <joint name="body_leg_2" type="revolute">
    <parent link="base_link"/>
    <child link="leg_2_1"/>
    <limit effort="30.0" lower="-1.57079632679" upper="1.57079632679" velocity="7.0"/>
    <origin rpy="0 0 -0.3" xyz="0.11 0.04 0"/>
    <!-- <xacro:if value="${index == 5 or index == 4 or index == 3}">
                <axis xyz="0 0 1"/>
            </xacro:if>
            <xacro:if value="${index == 2 or index == 1 or index == 0}"> -->
    <axis xyz="0 0 1"/>
    <!-- </xacro:if> -->
    <dynamics damping="0.0"/>
  </joint>
  <link name="leg_2_1">
    <visual>
      <origin rpy="1.57079632679 0 0" xyz="0.01 0.03 0"/>
      <geometry>
        <cylinder length="0.06" radius="0.02"/>
      </geometry>
      <material name="Red"/>
    </visual>
    <collision>
      <origin rpy="1.57079632679 0 0" xyz="0.01 0.03 0"/>
      <geometry>
        <box size="0.02 0.02 0.06"/>
      </geometry>
    </collision>
    <inertial>
      <!-- CENTER OF MASS -->
      <origin rpy="1.57079632679 0 0" xyz="0.01 0.03 0"/>
      <mass value="0.02"/>
      <!-- box inertia: 1/12*m(y^2+z^2), ... -->
      <inertia ixx="6.66666666667e-06" ixy="0" ixz="0" iyy="6.66666666667e-06" iyz="0" izz="1.33333333333e-06"/>
    </inertial>
  </link>
  <joint name="leg_2_1_2" type="revolute">
    <parent link="leg_2_1"/>
    <child link="leg_2_2"/>
    <limit effort="30.0" lower="-0.78539816339" upper="0.78539816339" velocity="7.0"/>
    <origin rpy="0 0 0" xyz="0 0.06 0"/>
    <axis xyz="1 0 0"/>
    <dynamics damping="0.0"/>
  </joint>
  <link name="leg_2_2">
    <visual>
      <origin rpy="1.57079632679 0 0" xyz="0.01 0.0257341644639 0"/>
      <geometry>
        <cylinder length="0.0514683289277" radius="0.02"/>
      </geometry>
      <material name="Blue"/>
    </visual>
    <collision>
      <origin rpy="1.57079632679 0 0" xyz="0.01 0.0257341644639 0"/>
      <geometry>
        <box size="0.02 0.02 0.0514683289277"/>
      </geometry>
    </collision>
    <inertial>
      <!-- CENTER OF MASS -->
      <origin rpy="1.57079632679 0 0" xyz="0.01 0.0257341644639 0"/>
      <mass value="0.184"/>
      <!-- box inertia: 1/12*m(y^2+z^2), ... -->
      <inertia ixx="4.67511628667e-05" ixy="0" ixz="0" iyy="4.67511628667e-05" iyz="0" izz="1.22666666667e-05"/>
    </inertial>
  </link>
  <joint name="leg_2_2_3" type="revolute">
    <parent link="leg_2_2"/>
    <child link="leg_2_3"/>
    <limit effort="30.0" lower="-0.78539816339" upper="0.78539816339" velocity="7.0"/>
    <origin rpy="-1.57079632679 0 0" xyz="0 0.0514683289277 0"/>
    <axis xyz="-1 0 0"/>
    <dynamics damping="0.0"/>
  </joint>
  <link name="leg_2_3">
    <visual>
      <origin rpy="1.57079632679 0 0" xyz="0.0125 0.0629492006525 0"/>
      <geometry>
        <cylinder length="0.125898401305" radius="0.025"/>
      </geometry>
      <material name="Red"/>
    </visual>
    <visual>
      <origin rpy="1.57079632679 0 0" xyz="0.0125 0.113398401305 0"/>
      <geometry>
        <sphere radius="0.025"/>
      </geometry>
      <material name="Red"/>
    </visual>
    <collision>
      <origin rpy="1.57079632679 0 0" xyz="0.0125 0.0629492006525 0"/>
      <geometry>
        <box size="0.025 0.025 0.125898401305"/>
      </geometry>
    </collision>
    <collision>
      <origin rpy="1.57079632679 0 0" xyz="0.0125 0.113398401305 0"/>
      <geometry>
        <sphere radius="0.025"/>
      </geometry>
      <material name="Red"/>
    </collision>
    <inertial>
      <!-- CENTER OF MASS -->
      <origin rpy="1.57079632679 0 0" xyz="0.0125 0.0629492006525 0"/>
      <mass value="0.04"/>
      <!-- box inertia: 1/12*m(y^2+z^2), ... -->
      <inertia ixx="5.49180248372e-05" ixy="0" ixz="0" iyy="5.49180248372e-05" iyz="0" izz="4.16666666667e-06"/>
    </inertial>
  </link>
  <joint name="body_leg_3" type="revolute">
    <parent link="base_link"/>
    <child link="leg_3_1"/>
    <limit effort="30.0" lower="-1.57079632679" upper="1.57079632679" velocity="7.0"/>
    <origin rpy="0 0 0.3" xyz="0.11 -0.04 0"/>
    <!-- <xacro:if value="${index == 5 or index == 4 or index == 3}">
                <axis xyz="0 0 1"/>
            </xacro:if>
            <xacro:if value="${index == 2 or index == 1 or index == 0}"> -->
    <axis xyz="0 0 1"/>
    <!-- </xacro:if> -->
    <dynamics damping="0.0"/>
  </joint>
  <link name="leg_3_1">
    <visual>
      <origin rpy="1.57079632679 0 0" xyz="0.01 -0.03 0"/>
      <geometry>
        <cylinder length="0.06" radius="0.02"/>
      </geometry>
      <material name="Red"/>
    </visual>
    <collision>
      <origin rpy="1.57079632679 0 0" xyz="0.01 -0.03 0"/>
      <geometry>
        <box size="0.02 0.02 0.06"/>
      </geometry>
    </collision>
    <inertial>
      <!-- CENTER OF MASS -->
      <origin rpy="1.57079632679 0 0" xyz="0.01 -0.03 0"/>
      <mass value="0.02"/>
      <!-- box inertia: 1/12*m(y^2+z^2), ... -->
      <inertia ixx="6.66666666667e-06" ixy="0" ixz="0" iyy="6.66666666667e-06" iyz="0" izz="1.33333333333e-06"/>
    </inertial>
  </link>
  <joint name="leg_3_1_2" type="revolute">
    <parent link="leg_3_1"/>
    <child link="leg_3_2"/>
    <limit effort="30.0" lower="-0.78539816339" upper="0.78539816339" velocity="7.0"/>
    <origin rpy="0 0 0" xyz="0 -0.06 0"/>
    <axis xyz="-1 0 0"/>
    <dynamics damping="0.0"/>
  </joint>
  <link name="leg_3_2">
    <visual>
      <origin rpy="1.57079632679 0 0" xyz="0.01 -0.0311463419801 0"/>
      <geometry>
        <cylinder length="0.0622926839601" radius="0.02"/>
      </geometry>
      <material name="Blue"/>
    </visual>
    <collision>
      <origin rpy="1.57079632679 0 0" xyz="0.01 -0.0311463419801 0"/>
      <geometry>
        <box size="0.02 0.02 0.0622926839601"/>
      </geometry>
    </collision>
    <inertial>
      <!-- CENTER OF MASS -->
      <origin rpy="1.57079632679 0 0" xyz="0.01 -0.0311463419801 0"/>
      <mass value="0.184"/>
      <!-- box inertia: 1/12*m(y^2+z^2), ... -->
      <inertia ixx="6.56324699493e-05" ixy="0" ixz="0" iyy="6.56324699493e-05" iyz="0" izz="1.22666666667e-05"/>
    </inertial>
  </link>
  <joint name="leg_3_2_3" type="revolute">
    <parent link="leg_3_2"/>
    <child link="leg_3_3"/>
    <limit effort="30.0" lower="-0.78539816339" upper="0.78539816339" velocity="7.0"/>
    <origin rpy="1.57079632679 0 0" xyz="0 -0.0622926839601 0"/>
    <axis xyz="1 0 0"/>
    <dynamics damping="0.0"/>
  </joint>
  <link name="leg_3_3">
    <visual>
      <origin rpy="1.57079632679 0 0" xyz="0.0125 -0.079878062301 0"/>
      <geometry>
        <cylinder length="0.159756124602" radius="0.025"/>
      </geometry>
      <material name="Red"/>
    </visual>
    <visual>
      <origin rpy="1.57079632679 0 0" xyz="0.0125 -0.147256124602 0"/>
      <geometry>
        <sphere radius="0.025"/>
      </geometry>
      <material name="Red"/>
    </visual>
    <collision>
      <origin rpy="1.57079632679 0 0" xyz="0.0125 -0.079878062301 0"/>
      <geometry>
        <box size="0.025 0.025 0.159756124602"/>
      </geometry>
    </collision>
    <collision>
      <origin rpy="1.57079632679 0 0" xyz="0.0125 -0.147256124602 0"/>
      <geometry>
        <sphere radius="0.025"/>
      </geometry>
      <material name="Red"/>
    </collision>
    <inertial>
      <!-- CENTER OF MASS -->
      <origin rpy="1.57079632679 0 0" xyz="0.0125 -0.079878062301 0"/>
      <mass value="0.04"/>
      <!-- box inertia: 1/12*m(y^2+z^2), ... -->
      <inertia ixx="8.71567311595e-05" ixy="0" ixz="0" iyy="8.71567311595e-05" iyz="0" izz="4.16666666667e-06"/>
    </inertial>
  </link>
  <joint name="body_leg_0" type="revolute">
    <parent link="base_link"/>
    <child link="leg_0_1"/>
    <limit effort="30.0" lower="-1.57079632679" upper="1.57079632679" velocity="7.0"/>
    <origin rpy="0 0 0.3" xyz="-0.13 0.04 0"/>
    <!-- <xacro:if value="${index == 5 or index == 4 or index == 3}">
                <axis xyz="0 0 1"/>
            </xacro:if>
            <xacro:if value="${index == 2 or index == 1 or index == 0}"> -->
    <axis xyz="0 0 1"/>
    <!-- </xacro:if> -->
    <dynamics damping="0.0"/>
  </joint>
  <link name="leg_0_1">
    <visual>
      <origin rpy="1.57079632679 0 0" xyz="0.01 0.03 0"/>
      <geometry>
        <cylinder length="0.06" radius="0.02"/>
      </geometry>
      <material name="Red"/>
    </visual>
    <collision>
      <origin rpy="1.57079632679 0 0" xyz="0.01 0.03 0"/>
      <geometry>
        <box size="0.02 0.02 0.06"/>
      </geometry>
    </collision>
    <inertial>
      <!-- CENTER OF MASS -->
      <origin rpy="1.57079632679 0 0" xyz="0.01 0.03 0"/>
      <mass value="0.02"/>
      <!-- box inertia: 1/12*m(y^2+z^2), ... -->
      <inertia ixx="6.66666666667e-06" ixy="0" ixz="0" iyy="6.66666666667e-06" iyz="0" izz="1.33333333333e-06"/>
    </inertial>
  </link>
  <joint name="leg_0_1_2" type="revolute">
    <parent link="leg_0_1"/>
    <child link="leg_0_2"/>
    <limit effort="30.0" lower="-0.78539816339" upper="0.78539816339" velocity="7.0"/>
    <origin rpy="0 0 0" xyz="0 0.06 0"/>
    <axis xyz="1 0 0"/>
    <dynamics damping="0.0"/>
  </joint>
  <link name="leg_0_2">
    <visual>
      <origin rpy="1.57079632679 0 0" xyz="0.01 0.0490292967196 0"/>
      <geometry>
        <cylinder length="0.0980585934391" radius="0.02"/>
      </geometry>
      <material name="Blue"/>
    </visual>
    <collision>
      <origin rpy="1.57079632679 0 0" xyz="0.01 0.0490292967196 0"/>
      <geometry>
        <box size="0.02 0.02 0.0980585934391"/>
      </geometry>
    </collision>
    <inertial>
      <!-- CENTER OF MASS -->
      <origin rpy="1.57079632679 0 0" xyz="0.01 0.0490292967196 0"/>
      <mass value="0.184"/>
      <!-- box inertia: 1/12*m(y^2+z^2), ... -->
      <inertia ixx="0.000153570812125" ixy="0" ixz="0" iyy="0.000153570812125" iyz="0" izz="1.22666666667e-05"/>
    </inertial>
  </link>
  <joint name="leg_0_2_3" type="revolute">
    <parent link="leg_0_2"/>
    <child link="leg_0_3"/>
    <limit effort="30.0" lower="-0.78539816339" upper="0.78539816339" velocity="7.0"/>
    <origin rpy="-1.57079632679 0 0" xyz="0 0.0980585934391 0"/>
    <axis xyz="-1 0 0"/>
    <dynamics damping="0.0"/>
  </joint>
  <link name="leg_0_3">
    <visual>
      <origin rpy="1.57079632679 0 0" xyz="0.0125 0.065900183128 0"/>
      <geometry>
        <cylinder length="0.131800366256" radius="0.025"/>
      </geometry>
      <material name="Red"/>
    </visual>
    <visual>
      <origin rpy="1.57079632679 0 0" xyz="0.0125 0.119300366256 0"/>
      <geometry>
        <sphere radius="0.025"/>
      </geometry>
      <material name="Red"/>
    </visual>
    <collision>
      <origin rpy="1.57079632679 0 0" xyz="0.0125 0.065900183128 0"/>
      <geometry>
        <box size="0.025 0.025 0.131800366256"/>
      </geometry>
    </collision>
    <collision>
      <origin rpy="1.57079632679 0 0" xyz="0.0125 0.119300366256 0"/>
      <geometry>
        <sphere radius="0.025"/>
      </geometry>
      <material name="Red"/>
    </collision>
    <inertial>
      <!-- CENTER OF MASS -->
      <origin rpy="1.57079632679 0 0" xyz="0.0125 0.065900183128 0"/>
      <mass value="0.04"/>
      <!-- box inertia: 1/12*m(y^2+z^2), ... -->
      <inertia ixx="5.99877884841e-05" ixy="0" ixz="0" iyy="5.99877884841e-05" iyz="0" izz="4.16666666667e-06"/>
    </inertial>
  </link>
  <joint name="body_leg_5" type="revolute">
    <parent link="base_link"/>
    <child link="leg_5_1"/>
    <limit effort="30.0" lower="-1.57079632679" upper="1.57079632679" velocity="7.0"/>
    <origin rpy="0 0 -0.3" xyz="-0.13 -0.04 0"/>
    <!-- <xacro:if value="${index == 5 or index == 4 or index == 3}">
                <axis xyz="0 0 1"/>
            </xacro:if>
            <xacro:if value="${index == 2 or index == 1 or index == 0}"> -->
    <axis xyz="0 0 1"/>
    <!-- </xacro:if> -->
    <dynamics damping="0.0"/>
  </joint>
  <link name="leg_5_1">
    <visual>
      <origin rpy="1.57079632679 0 0" xyz="0.01 -0.03 0"/>
      <geometry>
        <cylinder length="0.06" radius="0.02"/>
      </geometry>
      <material name="Red"/>
    </visual>
    <collision>
      <origin rpy="1.57079632679 0 0" xyz="0.01 -0.03 0"/>
      <geometry>
        <box size="0.02 0.02 0.06"/>
      </geometry>
    </collision>
    <inertial>
      <!-- CENTER OF MASS -->
      <origin rpy="1.57079632679 0 0" xyz="0.01 -0.03 0"/>
      <mass value="0.02"/>
      <!-- box inertia: 1/12*m(y^2+z^2), ... -->
      <inertia ixx="6.66666666667e-06" ixy="0" ixz="0" iyy="6.66666666667e-06" iyz="0" izz="1.33333333333e-06"/>
    </inertial>
  </link>
  <joint name="leg_5_1_2" type="revolute">
    <parent link="leg_5_1"/>
    <child link="leg_5_2"/>
    <limit effort="30.0" lower="-0.78539816339" upper="0.78539816339" velocity="7.0"/>
    <origin rpy="0 0 0" xyz="0 -0.06 0"/>
    <axis xyz="-1 0 0"/>
    <dynamics damping="0.0"/>
  </joint>
  <link name="leg_5_2">
    <visual>
      <origin rpy="1.57079632679 0 0" xyz="0.01 -0.0241266659585 0"/>
      <geometry>
        <cylinder length="0.0482533319171" radius="0.02"/>
      </geometry>
      <material name="Blue"/>
    </visual>
    <collision>
      <origin rpy="1.57079632679 0 0" xyz="0.01 -0.0241266659585 0"/>
      <geometry>
        <box size="0.02 0.02 0.0482533319171"/>
      </geometry>
    </collision>
    <inertial>
      <!-- CENTER OF MASS -->
      <origin rpy="1.57079632679 0 0" xyz="0.01 -0.0241266659585 0"/>
      <mass value="0.184"/>
      <!-- box inertia: 1/12*m(y^2+z^2), ... -->
      <inertia ixx="4.18352219636e-05" ixy="0" ixz="0" iyy="4.18352219636e-05" iyz="0" izz="1.22666666667e-05"/>
    </inertial>
  </link>
  <joint name="leg_5_2_3" type="revolute">
    <parent link="leg_5_2"/>
    <child link="leg_5_3"/>
    <limit effort="30.0" lower="-0.78539816339" upper="0.78539816339" velocity="7.0"/>
    <origin rpy="1.57079632679 0 0" xyz="0 -0.0482533319171 0"/>
    <axis xyz="1 0 0"/>
    <dynamics damping="0.0"/>
  </joint>
  <link name="leg_5_3">
    <visual>
      <origin rpy="1.57079632679 0 0" xyz="0.0125 -0.0612061075465 0"/>
      <geometry>
        <cylinder length="0.122412215093" radius="0.025"/>
      </geometry>
      <material name="Red"/>
    </visual>
    <visual>
      <origin rpy="1.57079632679 0 0" xyz="0.0125 -0.109912215093 0"/>
      <geometry>
        <sphere radius="0.025"/>
      </geometry>
      <material name="Red"/>
    </visual>
    <collision>
      <origin rpy="1.57079632679 0 0" xyz="0.0125 -0.0612061075465 0"/>
      <geometry>
        <box size="0.025 0.025 0.122412215093"/>
      </geometry>
    </collision>
    <collision>
      <origin rpy="1.57079632679 0 0" xyz="0.0125 -0.109912215093 0"/>
      <geometry>
        <sphere radius="0.025"/>
      </geometry>
      <material name="Red"/>
    </collision>
    <inertial>
      <!-- CENTER OF MASS -->
      <origin rpy="1.57079632679 0 0" xyz="0.0125 -0.0612061075465 0"/>
      <mass value="0.04"/>
      <!-- box inertia: 1/12*m(y^2+z^2), ... -->
      <inertia ixx="5.20325013466e-05" ixy="0" ixz="0" iyy="5.20325013466e-05" iyz="0" izz="4.16666666667e-06"/>
    </inertial>
  </link>
  <joint name="body_leg_1" type="revolute">
    <parent link="base_link"/>
    <child link="leg_1_1"/>
    <limit effort="30.0" lower="-1.57079632679" upper="1.57079632679" velocity="7.0"/>
    <origin rpy="0 0 0" xyz="-0.01 0.08 0"/>
    <!-- <xacro:if value="${index == 5 or index == 4 or index == 3}">
                <axis xyz="0 0 1"/>
            </xacro:if>
            <xacro:if value="${index == 2 or index == 1 or index == 0}"> -->
    <axis xyz="0 0 1"/>
    <!-- </xacro:if> -->
    <dynamics damping="0.0"/>
  </joint>
  <link name="leg_1_1">
    <visual>
      <origin rpy="1.57079632679 0 0" xyz="0.01 0.03 0"/>
      <geometry>
        <cylinder length="0.06" radius="0.02"/>
      </geometry>
      <material name="Red"/>
    </visual>
    <collision>
      <origin rpy="1.57079632679 0 0" xyz="0.01 0.03 0"/>
      <geometry>
        <box size="0.02 0.02 0.06"/>
      </geometry>
    </collision>
    <inertial>
      <!-- CENTER OF MASS -->
      <origin rpy="1.57079632679 0 0" xyz="0.01 0.03 0"/>
      <mass value="0.02"/>
      <!-- box inertia: 1/12*m(y^2+z^2), ... -->
      <inertia ixx="6.66666666667e-06" ixy="0" ixz="0" iyy="6.66666666667e-06" iyz="0" izz="1.33333333333e-06"/>
    </inertial>
  </link>
  <joint name="leg_1_1_2" type="revolute">
    <parent link="leg_1_1"/>
    <child link="leg_1_2"/>
    <limit effort="30.0" lower="-0.78539816339" upper="0.78539816339" velocity="7.0"/>
    <origin rpy="0 0 0" xyz="0 0.06 0"/>
    <axis xyz="1 0 0"/>
    <dynamics damping="0.0"/>
  </joint>
  <link name="leg_1_2">
    <visual>
      <origin rpy="1.57079632679 0 0" xyz="0.01 0.024151527888 0"/>
      <geometry>
        <cylinder length="0.0483030557759" radius="0.02"/>
      </geometry>
      <material name="Blue"/>
    </visual>
    <collision>
      <origin rpy="1.57079632679 0 0" xyz="0.01 0.024151527888 0"/>
      <geometry>
        <box size="0.02 0.02 0.0483030557759"/>
      </geometry>
    </collision>
    <inertial>
      <!-- CENTER OF MASS -->
      <origin rpy="1.57079632679 0 0" xyz="0.01 0.024151527888 0"/>
      <mass value="0.184"/>
      <!-- box inertia: 1/12*m(y^2+z^2), ... -->
      <inertia ixx="4.19088396918e-05" ixy="0" ixz="0" iyy="4.19088396918e-05" iyz="0" izz="1.22666666667e-05"/>
    </inertial>
  </link>
  <joint name="leg_1_2_3" type="revolute">
    <parent link="leg_1_2"/>
    <child link="leg_1_3"/>
    <limit effort="30.0" lower="-0.78539816339" upper="0.78539816339" velocity="7.0"/>
    <origin rpy="-1.57079632679 0 0" xyz="0 0.0483030557759 0"/>
    <axis xyz="-1 0 0"/>
    <dynamics damping="0.0"/>
  </joint>
  <link name="leg_1_3">
    <visual>
      <origin rpy="1.57079632679 0 0" xyz="0.0125 0.0514783365595 0"/>
      <geometry>
        <cylinder length="0.102956673119" radius="0.025"/>
      </geometry>
      <material name="Red"/>
    </visual>
    <visual>
      <origin rpy="1.57079632679 0 0" xyz="0.0125 0.090456673119 0"/>
      <geometry>
        <sphere radius="0.025"/>
      </geometry>
      <material name="Red"/>
    </visual>
    <collision>
      <origin rpy="1.57079632679 0 0" xyz="0.0125 0.0514783365595 0"/>
      <geometry>
        <box size="0.025 0.025 0.102956673119"/>
      </geometry>
    </collision>
    <collision>
      <origin rpy="1.57079632679 0 0" xyz="0.0125 0.090456673119 0"/>
      <geometry>
        <sphere radius="0.025"/>
      </geometry>
      <material name="Red"/>
    </collision>
    <inertial>
      <!-- CENTER OF MASS -->
      <origin rpy="1.57079632679 0 0" xyz="0.0125 0.0514783365595 0"/>
      <mass value="0.04"/>
      <!-- box inertia: 1/12*m(y^2+z^2), ... -->
      <inertia ixx="3.74169217991e-05" ixy="0" ixz="0" iyy="3.74169217991e-05" iyz="0" izz="4.16666666667e-06"/>
    </inertial>
  </link>
  <joint name="body_leg_4" type="revolute">
    <parent link="base_link"/>
    <child link="leg_4_1"/>
    <limit effort="30.0" lower="-1.57079632679" upper="1.57079632679" velocity="7.0"/>
    <origin rpy="0 0 0" xyz="-0.01 -0.08 0"/>
    <!-- <xacro:if value="${index == 5 or index == 4 or index == 3}">
                <axis xyz="0 0 1"/>
            </xacro:if>
            <xacro:if value="${index == 2 or index == 1 or index == 0}"> -->
    <axis xyz="0 0 1"/>
    <!-- </xacro:if> -->
    <dynamics damping="0.0"/>
  </joint>
  <link name="leg_4_1">
    <visual>
      <origin rpy="1.57079632679 0 0" xyz="0.01 -0.03 0"/>
      <geometry>
        <cylinder length="0.06" radius="0.02"/>
      </geometry>
      <material name="Red"/>
    </visual>
    <collision>
      <origin rpy="1.57079632679 0 0" xyz="0.01 -0.03 0"/>
      <geometry>
        <box size="0.02 0.02 0.06"/>
      </geometry>
    </collision>
    <inertial>
      <!-- CENTER OF MASS -->
      <origin rpy="1.57079632679 0 0" xyz="0.01 -0.03 0"/>
      <mass value="0.02"/>
      <!-- box inertia: 1/12*m(y^2+z^2), ... -->
      <inertia ixx="6.66666666667e-06" ixy="0" ixz="0" iyy="6.66666666667e-06" iyz="0" izz="1.33333333333e-06"/>
    </inertial>
  </link>
  <joint name="leg_4_1_2" type="revolute">
    <parent link="leg_4_1"/>
    <child link="leg_4_2"/>
    <limit effort="30.0" lower="-0.78539816339" upper="0.78539816339" velocity="7.0"/>
    <origin rpy="0 0 0" xyz="0 -0.06 0"/>
    <axis xyz="-1 0 0"/>
    <dynamics damping="0.0"/>
  </joint>
  <link name="leg_4_2">
    <visual>
      <origin rpy="1.57079632679 0 0" xyz="0.01 -0.0492500495749 0"/>
      <geometry>
        <cylinder length="0.0985000991498" radius="0.02"/>
      </geometry>
      <material name="Blue"/>
    </visual>
    <collision>
      <origin rpy="1.57079632679 0 0" xyz="0.01 -0.0492500495749 0"/>
      <geometry>
        <box size="0.02 0.02 0.0985000991498"/>
      </geometry>
    </collision>
    <inertial>
      <!-- CENTER OF MASS -->
      <origin rpy="1.57079632679 0 0" xyz="0.01 -0.0492500495749 0"/>
      <mass value="0.184"/>
      <!-- box inertia: 1/12*m(y^2+z^2), ... -->
      <inertia ixx="0.000154901466165" ixy="0" ixz="0" iyy="0.000154901466165" iyz="0" izz="1.22666666667e-05"/>
    </inertial>
  </link>
  <joint name="leg_4_2_3" type="revolute">
    <parent link="leg_4_2"/>
    <child link="leg_4_3"/>
    <limit effort="30.0" lower="-0.78539816339" upper="0.78539816339" velocity="7.0"/>
    <origin rpy="1.57079632679 0 0" xyz="0 -0.0985000991498 0"/>
    <axis xyz="1 0 0"/>
    <dynamics damping="0.0"/>
  </joint>
  <link name="leg_4_3">
    <visual>
      <origin rpy="1.57079632679 0 0" xyz="0.0125 -0.0823593186535 0"/>
      <geometry>
        <cylinder length="0.164718637307" radius="0.025"/>
      </geometry>
      <material name="Red"/>
    </visual>
    <visual>
      <origin rpy="1.57079632679 0 0" xyz="0.0125 -0.152218637307 0"/>
      <geometry>
        <sphere radius="0.025"/>
      </geometry>
      <material name="Red"/>
    </visual>
    <collision>
      <origin rpy="1.57079632679 0 0" xyz="0.0125 -0.0823593186535 0"/>
      <geometry>
        <box size="0.025 0.025 0.164718637307"/>
      </geometry>
    </collision>
    <collision>
      <origin rpy="1.57079632679 0 0" xyz="0.0125 -0.152218637307 0"/>
      <geometry>
        <sphere radius="0.025"/>
      </geometry>
      <material name="Red"/>
    </collision>
    <inertial>
      <!-- CENTER OF MASS -->
      <origin rpy="1.57079632679 0 0" xyz="0.0125 -0.0823593186535 0"/>
      <mass value="0.04"/>
      <!-- box inertia: 1/12*m(y^2+z^2), ... -->
      <inertia ixx="9.25240982543e-05" ixy="0" ixz="0" iyy="9.25240982543e-05" iyz="0" izz="4.16666666667e-06"/>
    </inertial>
  </link>
  <!-- END OF LEG LINKS/JOINTS -->
</robot>
