<?xml version="1.0" ?>
<!-- =================================================================================== -->
<!-- |    This document was autogenerated by xacro from pexod.xacro                    | -->
<!-- |    EDITING THIS FILE BY HAND IS NOT RECOMMENDED                                 | -->
<!-- =================================================================================== -->
<robot name="pexod" xmlns:xacro="http://www.ros.org/wiki/xacro">
  <!-- <xacro:include filename="$(find pexod_description)/urdf/pexod_control.xacro" /> -->
  <!-- MATERIALS -->
  <material name="Blue">
    <color rgba="0 0 1 1"/>
  </material>
  <material name="Red">
    <color rgba="1 0 0 1"/>
  </material>
  <material name="Green">
    <color rgba="0 1 0 1"/>
  </material>
  <material name="Yellow">
    <color rgba="1 1 0 1"/>
  </material>
  <material name="LightGrey">
    <color rgba="0.6 0.6 0.6 1.0"/>
  </material>
  <!-- END OF MATERIALS -->
  <!-- XACRO MACROS FOR VISUALS AND COLLISIONS -->
  <!-- END OF XACRO MACROS -->
  <!-- TORSO -->
  <link name="base_link">
    <visual>
      <origin rpy="0 0 0" xyz="0 0 0"/>
      <geometry>
        <box size="0.24 0.2 0.04"/>
      </geometry>
      <material name="Blue"/>
    </visual>
    <collision>
      <origin rpy="0 0 0" xyz="0 0 0"/>
      <geometry>
        <box size="0.24 0.2 0.04"/>
      </geometry>
    </collision>
    <inertial>
      <!-- CENTER OF MASS -->
      <origin rpy="0 0 0" xyz="0 0 0"/>
      <mass value="1.031"/>
      <!-- box inertia: 1/12*m(y^2+z^2), ... -->
      <inertia ixx="0.00357413333333" ixy="0" ixz="0" iyy="0.00508626666667" iyz="0" izz="0.00838546666667"/>
    </inertial>
  </link>
  <!-- XACRO MACRO FOR LEGS LINKS/JOINTS -->
  <!-- END OF LEG LINKS/JOINTS -->
  <joint name="body_leg_2" type="revolute">
    <parent link="base_link"/>
    <child link="leg_2_1"/>
    <limit effort="30.0" lower="-1.57079632679" upper="1.57079632679" velocity="7.0"/>
    <origin rpy="0 0 -0.3" xyz="0.11 0.04 0"/>
    <!-- <xacro:if value="${index == 5 or index == 4 or index == 3}">
                <axis xyz="0 0 1"/>
            </xacro:if>
            <xacro:if value="${index == 2 or index == 1 or index == 0}"> -->
    <axis xyz="0 0 1"/>
    <!-- </xacro:if> -->
    <dynamics damping="0.0"/>
  </joint>
  <link name="leg_2_1">
    <visual>
      <origin rpy="1.57079632679 0 0" xyz="0.01 0.03 0"/>
      <geometry>
        <cylinder length="0.06" radius="0.02"/>
      </geometry>
      <material name="Red"/>
    </visual>
    <collision>
      <origin rpy="1.57079632679 0 0" xyz="0.01 0.03 0"/>
      <geometry>
        <box size="0.02 0.02 0.06"/>
      </geometry>
    </collision>
    <inertial>
      <!-- CENTER OF MASS -->
      <origin rpy="1.57079632679 0 0" xyz="0.01 0.03 0"/>
      <mass value="0.02"/>
      <!-- box inertia: 1/12*m(y^2+z^2), ... -->
      <inertia ixx="6.66666666667e-06" ixy="0" ixz="0" iyy="6.66666666667e-06" iyz="0" izz="1.33333333333e-06"/>
    </inertial>
  </link>
  <joint name="leg_2_1_2" type="revolute">
    <parent link="leg_2_1"/>
    <child link="leg_2_2"/>
    <limit effort="30.0" lower="-0.78539816339" upper="0.78539816339" velocity="7.0"/>
    <origin rpy="0 0 0" xyz="0 0.06 0"/>
    <axis xyz="1 0 0"/>
    <dynamics damping="0.0"/>
  </joint>
  <link name="leg_2_2">
    <visual>
      <origin rpy="1.57079632679 0 0" xyz="0.01 0.0271400619211 0"/>
      <geometry>
        <cylinder length="0.0542801238422" radius="0.02"/>
      </geometry>
      <material name="Blue"/>
    </visual>
    <collision>
      <origin rpy="1.57079632679 0 0" xyz="0.01 0.0271400619211 0"/>
      <geometry>
        <box size="0.02 0.02 0.0542801238422"/>
      </geometry>
    </collision>
    <inertial>
      <!-- CENTER OF MASS -->
      <origin rpy="1.57079632679 0 0" xyz="0.01 0.0271400619211 0"/>
      <mass value="0.184"/>
      <!-- box inertia: 1/12*m(y^2+z^2), ... -->
      <inertia ixx="5.1310421613e-05" ixy="0" ixz="0" iyy="5.1310421613e-05" iyz="0" izz="1.22666666667e-05"/>
    </inertial>
  </link>
  <joint name="leg_2_2_3" type="revolute">
    <parent link="leg_2_2"/>
    <child link="leg_2_3"/>
    <limit effort="30.0" lower="-0.78539816339" upper="0.78539816339" velocity="7.0"/>
    <origin rpy="-1.57079632679 0 0" xyz="0 0.0542801238422 0"/>
    <axis xyz="-1 0 0"/>
    <dynamics damping="0.0"/>
  </joint>
  <link name="leg_2_3">
    <visual>
      <origin rpy="1.57079632679 0 0" xyz="0.0125 0.054601003364 0"/>
      <geometry>
        <cylinder length="0.109202006728" radius="0.025"/>
      </geometry>
      <material name="Red"/>
    </visual>
    <visual>
      <origin rpy="1.57079632679 0 0" xyz="0.0125 0.096702006728 0"/>
      <geometry>
        <sphere radius="0.025"/>
      </geometry>
      <material name="Red"/>
    </visual>
    <collision>
      <origin rpy="1.57079632679 0 0" xyz="0.0125 0.054601003364 0"/>
      <geometry>
        <box size="0.025 0.025 0.109202006728"/>
      </geometry>
    </collision>
    <collision>
      <origin rpy="1.57079632679 0 0" xyz="0.0125 0.096702006728 0"/>
      <geometry>
        <sphere radius="0.025"/>
      </geometry>
      <material name="Red"/>
    </collision>
    <inertial>
      <!-- CENTER OF MASS -->
      <origin rpy="1.57079632679 0 0" xyz="0.0125 0.054601003364 0"/>
      <mass value="0.04"/>
      <!-- box inertia: 1/12*m(y^2+z^2), ... -->
      <inertia ixx="4.18335942447e-05" ixy="0" ixz="0" iyy="4.18335942447e-05" iyz="0" izz="4.16666666667e-06"/>
    </inertial>
  </link>
  <joint name="body_leg_3" type="revolute">
    <parent link="base_link"/>
    <child link="leg_3_1"/>
    <limit effort="30.0" lower="-1.57079632679" upper="1.57079632679" velocity="7.0"/>
    <origin rpy="0 0 0.3" xyz="0.11 -0.04 0"/>
    <!-- <xacro:if value="${index == 5 or index == 4 or index == 3}">
                <axis xyz="0 0 1"/>
            </xacro:if>
            <xacro:if value="${index == 2 or index == 1 or index == 0}"> -->
    <axis xyz="0 0 1"/>
    <!-- </xacro:if> -->
    <dynamics damping="0.0"/>
  </joint>
  <link name="leg_3_1">
    <visual>
      <origin rpy="1.57079632679 0 0" xyz="0.01 -0.03 0"/>
      <geometry>
        <cylinder length="0.06" radius="0.02"/>
      </geometry>
      <material name="Red"/>
    </visual>
    <collision>
      <origin rpy="1.57079632679 0 0" xyz="0.01 -0.03 0"/>
      <geometry>
        <box size="0.02 0.02 0.06"/>
      </geometry>
    </collision>
    <inertial>
      <!-- CENTER OF MASS -->
      <origin rpy="1.57079632679 0 0" xyz="0.01 -0.03 0"/>
      <mass value="0.02"/>
      <!-- box inertia: 1/12*m(y^2+z^2), ... -->
      <inertia ixx="6.66666666667e-06" ixy="0" ixz="0" iyy="6.66666666667e-06" iyz="0" izz="1.33333333333e-06"/>
    </inertial>
  </link>
  <joint name="leg_3_1_2" type="revolute">
    <parent link="leg_3_1"/>
    <child link="leg_3_2"/>
    <limit effort="30.0" lower="-0.78539816339" upper="0.78539816339" velocity="7.0"/>
    <origin rpy="0 0 0" xyz="0 -0.06 0"/>
    <axis xyz="-1 0 0"/>
    <dynamics damping="0.0"/>
  </joint>
  <link name="leg_3_2">
    <visual>
      <origin rpy="1.57079632679 0 0" xyz="0.01 -0.0326648678378 0"/>
      <geometry>
        <cylinder length="0.0653297356755" radius="0.02"/>
      </geometry>
      <material name="Blue"/>
    </visual>
    <collision>
      <origin rpy="1.57079632679 0 0" xyz="0.01 -0.0326648678378 0"/>
      <geometry>
        <box size="0.02 0.02 0.0653297356755"/>
      </geometry>
    </collision>
    <inertial>
      <!-- CENTER OF MASS -->
      <origin rpy="1.57079632679 0 0" xyz="0.01 -0.0326648678378 0"/>
      <mass value="0.184"/>
      <!-- box inertia: 1/12*m(y^2+z^2), ... -->
      <inertia ixx="7.15756069059e-05" ixy="0" ixz="0" iyy="7.15756069059e-05" iyz="0" izz="1.22666666667e-05"/>
    </inertial>
  </link>
  <joint name="leg_3_2_3" type="revolute">
    <parent link="leg_3_2"/>
    <child link="leg_3_3"/>
    <limit effort="30.0" lower="-0.78539816339" upper="0.78539816339" velocity="7.0"/>
    <origin rpy="1.57079632679 0 0" xyz="0 -0.0653297356755 0"/>
    <axis xyz="1 0 0"/>
    <dynamics damping="0.0"/>
  </joint>
  <link name="leg_3_3">
    <visual>
      <origin rpy="1.57079632679 0 0" xyz="0.0125 -0.070845460954 0"/>
      <geometry>
        <cylinder length="0.141690921908" radius="0.025"/>
      </geometry>
      <material name="Red"/>
    </visual>
    <visual>
      <origin rpy="1.57079632679 0 0" xyz="0.0125 -0.129190921908 0"/>
      <geometry>
        <sphere radius="0.025"/>
      </geometry>
      <material name="Red"/>
    </visual>
    <collision>
      <origin rpy="1.57079632679 0 0" xyz="0.0125 -0.070845460954 0"/>
      <geometry>
        <box size="0.025 0.025 0.141690921908"/>
      </geometry>
    </collision>
    <collision>
      <origin rpy="1.57079632679 0 0" xyz="0.0125 -0.129190921908 0"/>
      <geometry>
        <sphere radius="0.025"/>
      </geometry>
      <material name="Red"/>
    </collision>
    <inertial>
      <!-- CENTER OF MASS -->
      <origin rpy="1.57079632679 0 0" xyz="0.0125 -0.070845460954 0"/>
      <mass value="0.04"/>
      <!-- box inertia: 1/12*m(y^2+z^2), ... -->
      <inertia ixx="6.90043911705e-05" ixy="0" ixz="0" iyy="6.90043911705e-05" iyz="0" izz="4.16666666667e-06"/>
    </inertial>
  </link>
  <joint name="body_leg_0" type="revolute">
    <parent link="base_link"/>
    <child link="leg_0_1"/>
    <limit effort="30.0" lower="-1.57079632679" upper="1.57079632679" velocity="7.0"/>
    <origin rpy="0 0 0.3" xyz="-0.13 0.04 0"/>
    <!-- <xacro:if value="${index == 5 or index == 4 or index == 3}">
                <axis xyz="0 0 1"/>
            </xacro:if>
            <xacro:if value="${index == 2 or index == 1 or index == 0}"> -->
    <axis xyz="0 0 1"/>
    <!-- </xacro:if> -->
    <dynamics damping="0.0"/>
  </joint>
  <link name="leg_0_1">
    <visual>
      <origin rpy="1.57079632679 0 0" xyz="0.01 0.03 0"/>
      <geometry>
        <cylinder length="0.06" radius="0.02"/>
      </geometry>
      <material name="Red"/>
    </visual>
    <collision>
      <origin rpy="1.57079632679 0 0" xyz="0.01 0.03 0"/>
      <geometry>
        <box size="0.02 0.02 0.06"/>
      </geometry>
    </collision>
    <inertial>
      <!-- CENTER OF MASS -->
      <origin rpy="1.57079632679 0 0" xyz="0.01 0.03 0"/>
      <mass value="0.02"/>
      <!-- box inertia: 1/12*m(y^2+z^2), ... -->
      <inertia ixx="6.66666666667e-06" ixy="0" ixz="0" iyy="6.66666666667e-06" iyz="0" izz="1.33333333333e-06"/>
    </inertial>
  </link>
  <joint name="leg_0_1_2" type="revolute">
    <parent link="leg_0_1"/>
    <child link="leg_0_2"/>
    <limit effort="30.0" lower="-0.78539816339" upper="0.78539816339" velocity="7.0"/>
    <origin rpy="0 0 0" xyz="0 0.06 0"/>
    <axis xyz="1 0 0"/>
    <dynamics damping="0.0"/>
  </joint>
  <link name="leg_0_2">
    <visual>
      <origin rpy="1.57079632679 0 0" xyz="0.01 0.0464257929834 0"/>
      <geometry>
        <cylinder length="0.0928515859668" radius="0.02"/>
      </geometry>
      <material name="Blue"/>
    </visual>
    <collision>
      <origin rpy="1.57079632679 0 0" xyz="0.01 0.0464257929834 0"/>
      <geometry>
        <box size="0.02 0.02 0.0928515859668"/>
      </geometry>
    </collision>
    <inertial>
      <!-- CENTER OF MASS -->
      <origin rpy="1.57079632679 0 0" xyz="0.01 0.0464257929834 0"/>
      <mass value="0.184"/>
      <!-- box inertia: 1/12*m(y^2+z^2), ... -->
      <inertia ixx="0.000138328394254" ixy="0" ixz="0" iyy="0.000138328394254" iyz="0" izz="1.22666666667e-05"/>
    </inertial>
  </link>
  <joint name="leg_0_2_3" type="revolute">
    <parent link="leg_0_2"/>
    <child link="leg_0_3"/>
    <limit effort="30.0" lower="-0.78539816339" upper="0.78539816339" velocity="7.0"/>
    <origin rpy="-1.57079632679 0 0" xyz="0 0.0928515859668 0"/>
    <axis xyz="-1 0 0"/>
    <dynamics damping="0.0"/>
  </joint>
  <link name="leg_0_3">
    <visual>
      <origin rpy="1.57079632679 0 0" xyz="0.0125 0.066967520277 0"/>
      <geometry>
        <cylinder length="0.133935040554" radius="0.025"/>
      </geometry>
      <material name="Red"/>
    </visual>
    <visual>
      <origin rpy="1.57079632679 0 0" xyz="0.0125 0.121435040554 0"/>
      <geometry>
        <sphere radius="0.025"/>
      </geometry>
      <material name="Red"/>
    </visual>
    <collision>
      <origin rpy="1.57079632679 0 0" xyz="0.0125 0.066967520277 0"/>
      <geometry>
        <box size="0.025 0.025 0.133935040554"/>
      </geometry>
    </collision>
    <collision>
      <origin rpy="1.57079632679 0 0" xyz="0.0125 0.121435040554 0"/>
      <geometry>
        <sphere radius="0.025"/>
      </geometry>
      <material name="Red"/>
    </collision>
    <inertial>
      <!-- CENTER OF MASS -->
      <origin rpy="1.57079632679 0 0" xyz="0.0125 0.066967520277 0"/>
      <mass value="0.04"/>
      <!-- box inertia: 1/12*m(y^2+z^2), ... -->
      <inertia ixx="6.1878650294e-05" ixy="0" ixz="0" iyy="6.1878650294e-05" iyz="0" izz="4.16666666667e-06"/>
    </inertial>
  </link>
  <joint name="body_leg_5" type="revolute">
    <parent link="base_link"/>
    <child link="leg_5_1"/>
    <limit effort="30.0" lower="-1.57079632679" upper="1.57079632679" velocity="7.0"/>
    <origin rpy="0 0 -0.3" xyz="-0.13 -0.04 0"/>
    <!-- <xacro:if value="${index == 5 or index == 4 or index == 3}">
                <axis xyz="0 0 1"/>
            </xacro:if>
            <xacro:if value="${index == 2 or index == 1 or index == 0}"> -->
    <axis xyz="0 0 1"/>
    <!-- </xacro:if> -->
    <dynamics damping="0.0"/>
  </joint>
  <link name="leg_5_1">
    <visual>
      <origin rpy="1.57079632679 0 0" xyz="0.01 -0.03 0"/>
      <geometry>
        <cylinder length="0.06" radius="0.02"/>
      </geometry>
      <material name="Red"/>
    </visual>
    <collision>
      <origin rpy="1.57079632679 0 0" xyz="0.01 -0.03 0"/>
      <geometry>
        <box size="0.02 0.02 0.06"/>
      </geometry>
    </collision>
    <inertial>
      <!-- CENTER OF MASS -->
      <origin rpy="1.57079632679 0 0" xyz="0.01 -0.03 0"/>
      <mass value="0.02"/>
      <!-- box inertia: 1/12*m(y^2+z^2), ... -->
      <inertia ixx="6.66666666667e-06" ixy="0" ixz="0" iyy="6.66666666667e-06" iyz="0" izz="1.33333333333e-06"/>
    </inertial>
  </link>
  <joint name="leg_5_1_2" type="revolute">
    <parent link="leg_5_1"/>
    <child link="leg_5_2"/>
    <limit effort="30.0" lower="-0.78539816339" upper="0.78539816339" velocity="7.0"/>
    <origin rpy="0 0 0" xyz="0 -0.06 0"/>
    <axis xyz="-1 0 0"/>
    <dynamics damping="0.0"/>
  </joint>
  <link name="leg_5_2">
    <visual>
      <origin rpy="1.57079632679 0 0" xyz="0.01 -0.0589905024235 0"/>
      <geometry>
        <cylinder length="0.117981004847" radius="0.02"/>
      </geometry>
      <material name="Blue"/>
    </visual>
    <collision>
      <origin rpy="1.57079632679 0 0" xyz="0.01 -0.0589905024235 0"/>
      <geometry>
        <box size="0.02 0.02 0.117981004847"/>
      </geometry>
    </collision>
    <inertial>
      <!-- CENTER OF MASS -->
      <origin rpy="1.57079632679 0 0" xyz="0.01 -0.0589905024235 0"/>
      <mass value="0.184"/>
      <!-- box inertia: 1/12*m(y^2+z^2), ... -->
      <inertia ixx="0.000219565935072" ixy="0" ixz="0" iyy="0.000219565935072" iyz="0" izz="1.22666666667e-05"/>
    </inertial>
  </link>
  <joint name="leg_5_2_3" type="revolute">
    <parent link="leg_5_2"/>
    <child link="leg_5_3"/>
    <limit effort="30.0" lower="-0.78539816339" upper="0.78539816339" velocity="7.0"/>
    <origin rpy="1.57079632679 0 0" xyz="0 -0.117981004847 0"/>
    <axis xyz="1 0 0"/>
    <dynamics damping="0.0"/>
  </joint>
  <link name="leg_5_3">
    <visual>
      <origin rpy="1.57079632679 0 0" xyz="0.0125 -0.0883112410755 0"/>
      <geometry>
        <cylinder length="0.176622482151" radius="0.025"/>
      </geometry>
      <material name="Red"/>
    </visual>
    <visual>
      <origin rpy="1.57079632679 0 0" xyz="0.0125 -0.164122482151 0"/>
      <geometry>
        <sphere radius="0.025"/>
      </geometry>
      <material name="Red"/>
    </visual>
    <collision>
      <origin rpy="1.57079632679 0 0" xyz="0.0125 -0.0883112410755 0"/>
      <geometry>
        <box size="0.025 0.025 0.176622482151"/>
      </geometry>
    </collision>
    <collision>
      <origin rpy="1.57079632679 0 0" xyz="0.0125 -0.164122482151 0"/>
      <geometry>
        <sphere radius="0.025"/>
      </geometry>
      <material name="Red"/>
    </collision>
    <inertial>
      <!-- CENTER OF MASS -->
      <origin rpy="1.57079632679 0 0" xyz="0.0125 -0.0883112410755 0"/>
      <mass value="0.04"/>
      <!-- box inertia: 1/12*m(y^2+z^2), ... -->
      <inertia ixx="0.000106068337337" ixy="0" ixz="0" iyy="0.000106068337337" iyz="0" izz="4.16666666667e-06"/>
    </inertial>
  </link>
  <joint name="body_leg_1" type="revolute">
    <parent link="base_link"/>
    <child link="leg_1_1"/>
    <limit effort="30.0" lower="-1.57079632679" upper="1.57079632679" velocity="7.0"/>
    <origin rpy="0 0 0" xyz="-0.01 0.08 0"/>
    <!-- <xacro:if value="${index == 5 or index == 4 or index == 3}">
                <axis xyz="0 0 1"/>
            </xacro:if>
            <xacro:if value="${index == 2 or index == 1 or index == 0}"> -->
    <axis xyz="0 0 1"/>
    <!-- </xacro:if> -->
    <dynamics damping="0.0"/>
  </joint>
  <link name="leg_1_1">
    <visual>
      <origin rpy="1.57079632679 0 0" xyz="0.01 0.03 0"/>
      <geometry>
        <cylinder length="0.06" radius="0.02"/>
      </geometry>
      <material name="Red"/>
    </visual>
    <collision>
      <origin rpy="1.57079632679 0 0" xyz="0.01 0.03 0"/>
      <geometry>
        <box size="0.02 0.02 0.06"/>
      </geometry>
    </collision>
    <inertial>
      <!-- CENTER OF MASS -->
      <origin rpy="1.57079632679 0 0" xyz="0.01 0.03 0"/>
      <mass value="0.02"/>
      <!-- box inertia: 1/12*m(y^2+z^2), ... -->
      <inertia ixx="6.66666666667e-06" ixy="0" ixz="0" iyy="6.66666666667e-06" iyz="0" izz="1.33333333333e-06"/>
    </inertial>
  </link>
  <joint name="leg_1_1_2" type="revolute">
    <parent link="leg_1_1"/>
    <child link="leg_1_2"/>
    <limit effort="30.0" lower="-0.78539816339" upper="0.78539816339" velocity="7.0"/>
    <origin rpy="0 0 0" xyz="0 0.06 0"/>
    <axis xyz="1 0 0"/>
    <dynamics damping="0.0"/>
  </joint>
  <link name="leg_1_2">
    <visual>
      <origin rpy="1.57079632679 0 0" xyz="0.01 0.0373259091849 0"/>
      <geometry>
        <cylinder length="0.0746518183697" radius="0.02"/>
      </geometry>
      <material name="Blue"/>
    </visual>
    <collision>
      <origin rpy="1.57079632679 0 0" xyz="0.01 0.0373259091849 0"/>
      <geometry>
        <box size="0.02 0.02 0.0746518183697"/>
      </geometry>
    </collision>
    <inertial>
      <!-- CENTER OF MASS -->
      <origin rpy="1.57079632679 0 0" xyz="0.01 0.0373259091849 0"/>
      <mass value="0.184"/>
      <!-- box inertia: 1/12*m(y^2+z^2), ... -->
      <inertia ixx="9.15843744505e-05" ixy="0" ixz="0" iyy="9.15843744505e-05" iyz="0" izz="1.22666666667e-05"/>
    </inertial>
  </link>
  <joint name="leg_1_2_3" type="revolute">
    <parent link="leg_1_2"/>
    <child link="leg_1_3"/>
    <limit effort="30.0" lower="-0.78539816339" upper="0.78539816339" velocity="7.0"/>
    <origin rpy="-1.57079632679 0 0" xyz="0 0.0746518183697 0"/>
    <axis xyz="-1 0 0"/>
    <dynamics damping="0.0"/>
  </joint>
  <link name="leg_1_3">
    <visual>
      <origin rpy="1.57079632679 0 0" xyz="0.0125 0.07292089228 0"/>
      <geometry>
        <cylinder length="0.14584178456" radius="0.025"/>
      </geometry>
      <material name="Red"/>
    </visual>
    <visual>
      <origin rpy="1.57079632679 0 0" xyz="0.0125 0.13334178456 0"/>
      <geometry>
        <sphere radius="0.025"/>
      </geometry>
      <material name="Red"/>
    </visual>
    <collision>
      <origin rpy="1.57079632679 0 0" xyz="0.0125 0.07292089228 0"/>
      <geometry>
        <box size="0.025 0.025 0.14584178456"/>
      </geometry>
    </collision>
    <collision>
      <origin rpy="1.57079632679 0 0" xyz="0.0125 0.13334178456 0"/>
      <geometry>
        <sphere radius="0.025"/>
      </geometry>
      <material name="Red"/>
    </collision>
    <inertial>
      <!-- CENTER OF MASS -->
      <origin rpy="1.57079632679 0 0" xyz="0.0125 0.07292089228 0"/>
      <mass value="0.04"/>
      <!-- box inertia: 1/12*m(y^2+z^2), ... -->
      <inertia ixx="7.29827537455e-05" ixy="0" ixz="0" iyy="7.29827537455e-05" iyz="0" izz="4.16666666667e-06"/>
    </inertial>
  </link>
  <joint name="body_leg_4" type="revolute">
    <parent link="base_link"/>
    <child link="leg_4_1"/>
    <limit effort="30.0" lower="-1.57079632679" upper="1.57079632679" velocity="7.0"/>
    <origin rpy="0 0 0" xyz="-0.01 -0.08 0"/>
    <!-- <xacro:if value="${index == 5 or index == 4 or index == 3}">
                <axis xyz="0 0 1"/>
            </xacro:if>
            <xacro:if value="${index == 2 or index == 1 or index == 0}"> -->
    <axis xyz="0 0 1"/>
    <!-- </xacro:if> -->
    <dynamics damping="0.0"/>
  </joint>
  <link name="leg_4_1">
    <visual>
      <origin rpy="1.57079632679 0 0" xyz="0.01 -0.03 0"/>
      <geometry>
        <cylinder length="0.06" radius="0.02"/>
      </geometry>
      <material name="Red"/>
    </visual>
    <collision>
      <origin rpy="1.57079632679 0 0" xyz="0.01 -0.03 0"/>
      <geometry>
        <box size="0.02 0.02 0.06"/>
      </geometry>
    </collision>
    <inertial>
      <!-- CENTER OF MASS -->
      <origin rpy="1.57079632679 0 0" xyz="0.01 -0.03 0"/>
      <mass value="0.02"/>
      <!-- box inertia: 1/12*m(y^2+z^2), ... -->
      <inertia ixx="6.66666666667e-06" ixy="0" ixz="0" iyy="6.66666666667e-06" iyz="0" izz="1.33333333333e-06"/>
    </inertial>
  </link>
  <joint name="leg_4_1_2" type="revolute">
    <parent link="leg_4_1"/>
    <child link="leg_4_2"/>
    <limit effort="30.0" lower="-0.78539816339" upper="0.78539816339" velocity="7.0"/>
    <origin rpy="0 0 0" xyz="0 -0.06 0"/>
    <axis xyz="-1 0 0"/>
    <dynamics damping="0.0"/>
  </joint>
  <link name="leg_4_2">
    <visual>
      <origin rpy="1.57079632679 0 0" xyz="0.01 -0.0278231598638 0"/>
      <geometry>
        <cylinder length="0.0556463197276" radius="0.02"/>
      </geometry>
      <material name="Blue"/>
    </visual>
    <collision>
      <origin rpy="1.57079632679 0 0" xyz="0.01 -0.0278231598638 0"/>
      <geometry>
        <box size="0.02 0.02 0.0556463197276"/>
      </geometry>
    </collision>
    <inertial>
      <!-- CENTER OF MASS -->
      <origin rpy="1.57079632679 0 0" xyz="0.01 -0.0278231598638 0"/>
      <mass value="0.184"/>
      <!-- box inertia: 1/12*m(y^2+z^2), ... -->
      <inertia ixx="5.36131977881e-05" ixy="0" ixz="0" iyy="5.36131977881e-05" iyz="0" izz="1.22666666667e-05"/>
    </inertial>
  </link>
  <joint name="leg_4_2_3" type="revolute">
    <parent link="leg_4_2"/>
    <child link="leg_4_3"/>
    <limit effort="30.0" lower="-0.78539816339" upper="0.78539816339" velocity="7.0"/>
    <origin rpy="1.57079632679 0 0" xyz="0 -0.0556463197276 0"/>
    <axis xyz="1 0 0"/>
    <dynamics damping="0.0"/>
  </joint>
  <link name="leg_4_3">
    <visual>
      <origin rpy="1.57079632679 0 0" xyz="0.0125 -0.056820932486 0"/>
      <geometry>
        <cylinder length="0.113641864972" radius="0.025"/>
      </geometry>
      <material name="Red"/>
    </visual>
    <visual>
      <origin rpy="1.57079632679 0 0" xyz="0.0125 -0.101141864972 0"/>
      <geometry>
        <sphere radius="0.025"/>
      </geometry>
      <material name="Red"/>
    </visual>
    <collision>
      <origin rpy="1.57079632679 0 0" xyz="0.0125 -0.056820932486 0"/>
      <geometry>
        <box size="0.025 0.025 0.113641864972"/>
      </geometry>
    </collision>
    <collision>
      <origin rpy="1.57079632679 0 0" xyz="0.0125 -0.101141864972 0"/>
      <geometry>
        <sphere radius="0.025"/>
      </geometry>
      <material name="Red"/>
    </collision>
    <inertial>
      <!-- CENTER OF MASS -->
      <origin rpy="1.57079632679 0 0" xyz="0.0125 -0.056820932486 0"/>
      <mass value="0.04"/>
      <!-- box inertia: 1/12*m(y^2+z^2), ... -->
      <inertia ixx="4.51315782477e-05" ixy="0" ixz="0" iyy="4.51315782477e-05" iyz="0" izz="4.16666666667e-06"/>
    </inertial>
  </link>
  <!-- END OF LEG LINKS/JOINTS -->
</robot>
