<?xml version="1.0" ?>
<!-- =================================================================================== -->
<!-- |    This document was autogenerated by xacro from pexod.xacro                    | -->
<!-- |    EDITING THIS FILE BY HAND IS NOT RECOMMENDED                                 | -->
<!-- =================================================================================== -->
<robot name="pexod" xmlns:xacro="http://www.ros.org/wiki/xacro">
  <!-- <xacro:include filename="$(find pexod_description)/urdf/pexod_control.xacro" /> -->
  <!-- MATERIALS -->
  <material name="Blue">
    <color rgba="0 0 1 1"/>
  </material>
  <material name="Red">
    <color rgba="1 0 0 1"/>
  </material>
  <material name="Green">
    <color rgba="0 1 0 1"/>
  </material>
  <material name="Yellow">
    <color rgba="1 1 0 1"/>
  </material>
  <material name="LightGrey">
    <color rgba="0.6 0.6 0.6 1.0"/>
  </material>
  <!-- END OF MATERIALS -->
  <!-- XACRO MACROS FOR VISUALS AND COLLISIONS -->
  <!-- END OF XACRO MACROS -->
  <!-- TORSO -->
  <link name="base_link">
    <visual>
      <origin rpy="0 0 0" xyz="0 0 0"/>
      <geometry>
        <box size="0.24 0.2 0.04"/>
      </geometry>
      <material name="Blue"/>
    </visual>
    <collision>
      <origin rpy="0 0 0" xyz="0 0 0"/>
      <geometry>
        <box size="0.24 0.2 0.04"/>
      </geometry>
    </collision>
    <inertial>
      <!-- CENTER OF MASS -->
      <origin rpy="0 0 0" xyz="0 0 0"/>
      <mass value="1.031"/>
      <!-- box inertia: 1/12*m(y^2+z^2), ... -->
      <inertia ixx="0.00357413333333" ixy="0" ixz="0" iyy="0.00508626666667" iyz="0" izz="0.00838546666667"/>
    </inertial>
  </link>
  <!-- XACRO MACRO FOR LEGS LINKS/JOINTS -->
  <!-- END OF LEG LINKS/JOINTS -->
  <joint name="body_leg_2" type="revolute">
    <parent link="base_link"/>
    <child link="leg_2_1"/>
    <limit effort="30.0" lower="-1.57079632679" upper="1.57079632679" velocity="7.0"/>
    <origin rpy="0 0 -0.3" xyz="0.11 0.04 0"/>
    <!-- <xacro:if value="${index == 5 or index == 4 or index == 3}">
                <axis xyz="0 0 1"/>
            </xacro:if>
            <xacro:if value="${index == 2 or index == 1 or index == 0}"> -->
    <axis xyz="0 0 1"/>
    <!-- </xacro:if> -->
    <dynamics damping="0.0"/>
  </joint>
  <link name="leg_2_1">
    <visual>
      <origin rpy="1.57079632679 0 0" xyz="0.01 0.03 0"/>
      <geometry>
        <cylinder length="0.06" radius="0.02"/>
      </geometry>
      <material name="Red"/>
    </visual>
    <collision>
      <origin rpy="1.57079632679 0 0" xyz="0.01 0.03 0"/>
      <geometry>
        <box size="0.02 0.02 0.06"/>
      </geometry>
    </collision>
    <inertial>
      <!-- CENTER OF MASS -->
      <origin rpy="1.57079632679 0 0" xyz="0.01 0.03 0"/>
      <mass value="0.02"/>
      <!-- box inertia: 1/12*m(y^2+z^2), ... -->
      <inertia ixx="6.66666666667e-06" ixy="0" ixz="0" iyy="6.66666666667e-06" iyz="0" izz="1.33333333333e-06"/>
    </inertial>
  </link>
  <joint name="leg_2_1_2" type="revolute">
    <parent link="leg_2_1"/>
    <child link="leg_2_2"/>
    <limit effort="30.0" lower="-0.78539816339" upper="0.78539816339" velocity="7.0"/>
    <origin rpy="0 0 0" xyz="0 0.06 0"/>
    <axis xyz="1 0 0"/>
    <dynamics damping="0.0"/>
  </joint>
  <link name="leg_2_2">
    <visual>
      <origin rpy="1.57079632679 0 0" xyz="0.01 0.0373734870932 0"/>
      <geometry>
        <cylinder length="0.0747469741864" radius="0.02"/>
      </geometry>
      <material name="Blue"/>
    </visual>
    <collision>
      <origin rpy="1.57079632679 0 0" xyz="0.01 0.0373734870932 0"/>
      <geometry>
        <box size="0.02 0.02 0.0747469741864"/>
      </geometry>
    </collision>
    <inertial>
      <!-- CENTER OF MASS -->
      <origin rpy="1.57079632679 0 0" xyz="0.01 0.0373734870932 0"/>
      <mass value="0.184"/>
      <!-- box inertia: 1/12*m(y^2+z^2), ... -->
      <inertia ixx="9.18023556337e-05" ixy="0" ixz="0" iyy="9.18023556337e-05" iyz="0" izz="1.22666666667e-05"/>
    </inertial>
  </link>
  <joint name="leg_2_2_3" type="revolute">
    <parent link="leg_2_2"/>
    <child link="leg_2_3"/>
    <limit effort="30.0" lower="-0.78539816339" upper="0.78539816339" velocity="7.0"/>
    <origin rpy="-1.57079632679 0 0" xyz="0 0.0747469741864 0"/>
    <axis xyz="-1 0 0"/>
    <dynamics damping="0.0"/>
  </joint>
  <link name="leg_2_3">
    <visual>
      <origin rpy="1.57079632679 0 0" xyz="0.0125 0.0611928900805 0"/>
      <geometry>
        <cylinder length="0.122385780161" radius="0.025"/>
      </geometry>
      <material name="Red"/>
    </visual>
    <visual>
      <origin rpy="1.57079632679 0 0" xyz="0.0125 0.109885780161 0"/>
      <geometry>
        <sphere radius="0.025"/>
      </geometry>
      <material name="Red"/>
    </visual>
    <collision>
      <origin rpy="1.57079632679 0 0" xyz="0.0125 0.0611928900805 0"/>
      <geometry>
        <box size="0.025 0.025 0.122385780161"/>
      </geometry>
    </collision>
    <collision>
      <origin rpy="1.57079632679 0 0" xyz="0.0125 0.109885780161 0"/>
      <geometry>
        <sphere radius="0.025"/>
      </geometry>
      <material name="Red"/>
    </collision>
    <inertial>
      <!-- CENTER OF MASS -->
      <origin rpy="1.57079632679 0 0" xyz="0.0125 0.0611928900805 0"/>
      <mass value="0.04"/>
      <!-- box inertia: 1/12*m(y^2+z^2), ... -->
      <inertia ixx="5.20109306187e-05" ixy="0" ixz="0" iyy="5.20109306187e-05" iyz="0" izz="4.16666666667e-06"/>
    </inertial>
  </link>
  <joint name="body_leg_3" type="revolute">
    <parent link="base_link"/>
    <child link="leg_3_1"/>
    <limit effort="30.0" lower="-1.57079632679" upper="1.57079632679" velocity="7.0"/>
    <origin rpy="0 0 0.3" xyz="0.11 -0.04 0"/>
    <!-- <xacro:if value="${index == 5 or index == 4 or index == 3}">
                <axis xyz="0 0 1"/>
            </xacro:if>
            <xacro:if value="${index == 2 or index == 1 or index == 0}"> -->
    <axis xyz="0 0 1"/>
    <!-- </xacro:if> -->
    <dynamics damping="0.0"/>
  </joint>
  <link name="leg_3_1">
    <visual>
      <origin rpy="1.57079632679 0 0" xyz="0.01 -0.03 0"/>
      <geometry>
        <cylinder length="0.06" radius="0.02"/>
      </geometry>
      <material name="Red"/>
    </visual>
    <collision>
      <origin rpy="1.57079632679 0 0" xyz="0.01 -0.03 0"/>
      <geometry>
        <box size="0.02 0.02 0.06"/>
      </geometry>
    </collision>
    <inertial>
      <!-- CENTER OF MASS -->
      <origin rpy="1.57079632679 0 0" xyz="0.01 -0.03 0"/>
      <mass value="0.02"/>
      <!-- box inertia: 1/12*m(y^2+z^2), ... -->
      <inertia ixx="6.66666666667e-06" ixy="0" ixz="0" iyy="6.66666666667e-06" iyz="0" izz="1.33333333333e-06"/>
    </inertial>
  </link>
  <joint name="leg_3_1_2" type="revolute">
    <parent link="leg_3_1"/>
    <child link="leg_3_2"/>
    <limit effort="30.0" lower="-0.78539816339" upper="0.78539816339" velocity="7.0"/>
    <origin rpy="0 0 0" xyz="0 -0.06 0"/>
    <axis xyz="-1 0 0"/>
    <dynamics damping="0.0"/>
  </joint>
  <link name="leg_3_2">
    <visual>
      <origin rpy="1.57079632679 0 0" xyz="0.01 -0.054383764901 0"/>
      <geometry>
        <cylinder length="0.108767529802" radius="0.02"/>
      </geometry>
      <material name="Blue"/>
    </visual>
    <collision>
      <origin rpy="1.57079632679 0 0" xyz="0.01 -0.054383764901 0"/>
      <geometry>
        <box size="0.02 0.02 0.108767529802"/>
      </geometry>
    </collision>
    <inertial>
      <!-- CENTER OF MASS -->
      <origin rpy="1.57079632679 0 0" xyz="0.01 -0.054383764901 0"/>
      <mass value="0.184"/>
      <!-- box inertia: 1/12*m(y^2+z^2), ... -->
      <inertia ixx="0.000187532424935" ixy="0" ixz="0" iyy="0.000187532424935" iyz="0" izz="1.22666666667e-05"/>
    </inertial>
  </link>
  <joint name="leg_3_2_3" type="revolute">
    <parent link="leg_3_2"/>
    <child link="leg_3_3"/>
    <limit effort="30.0" lower="-0.78539816339" upper="0.78539816339" velocity="7.0"/>
    <origin rpy="1.57079632679 0 0" xyz="0 -0.108767529802 0"/>
    <axis xyz="1 0 0"/>
    <dynamics damping="0.0"/>
  </joint>
  <link name="leg_3_3">
    <visual>
      <origin rpy="1.57079632679 0 0" xyz="0.0125 -0.0854805447965 0"/>
      <geometry>
        <cylinder length="0.170961089593" radius="0.025"/>
      </geometry>
      <material name="Red"/>
    </visual>
    <visual>
      <origin rpy="1.57079632679 0 0" xyz="0.0125 -0.158461089593 0"/>
      <geometry>
        <sphere radius="0.025"/>
      </geometry>
      <material name="Red"/>
    </visual>
    <collision>
      <origin rpy="1.57079632679 0 0" xyz="0.0125 -0.0854805447965 0"/>
      <geometry>
        <box size="0.025 0.025 0.170961089593"/>
      </geometry>
    </collision>
    <collision>
      <origin rpy="1.57079632679 0 0" xyz="0.0125 -0.158461089593 0"/>
      <geometry>
        <sphere radius="0.025"/>
      </geometry>
      <material name="Red"/>
    </collision>
    <inertial>
      <!-- CENTER OF MASS -->
      <origin rpy="1.57079632679 0 0" xyz="0.0125 -0.0854805447965 0"/>
      <mass value="0.04"/>
      <!-- box inertia: 1/12*m(y^2+z^2), ... -->
      <inertia ixx="9.95089805161e-05" ixy="0" ixz="0" iyy="9.95089805161e-05" iyz="0" izz="4.16666666667e-06"/>
    </inertial>
  </link>
  <joint name="body_leg_0" type="revolute">
    <parent link="base_link"/>
    <child link="leg_0_1"/>
    <limit effort="30.0" lower="-1.57079632679" upper="1.57079632679" velocity="7.0"/>
    <origin rpy="0 0 0.3" xyz="-0.13 0.04 0"/>
    <!-- <xacro:if value="${index == 5 or index == 4 or index == 3}">
                <axis xyz="0 0 1"/>
            </xacro:if>
            <xacro:if value="${index == 2 or index == 1 or index == 0}"> -->
    <axis xyz="0 0 1"/>
    <!-- </xacro:if> -->
    <dynamics damping="0.0"/>
  </joint>
  <link name="leg_0_1">
    <visual>
      <origin rpy="1.57079632679 0 0" xyz="0.01 0.03 0"/>
      <geometry>
        <cylinder length="0.06" radius="0.02"/>
      </geometry>
      <material name="Red"/>
    </visual>
    <collision>
      <origin rpy="1.57079632679 0 0" xyz="0.01 0.03 0"/>
      <geometry>
        <box size="0.02 0.02 0.06"/>
      </geometry>
    </collision>
    <inertial>
      <!-- CENTER OF MASS -->
      <origin rpy="1.57079632679 0 0" xyz="0.01 0.03 0"/>
      <mass value="0.02"/>
      <!-- box inertia: 1/12*m(y^2+z^2), ... -->
      <inertia ixx="6.66666666667e-06" ixy="0" ixz="0" iyy="6.66666666667e-06" iyz="0" izz="1.33333333333e-06"/>
    </inertial>
  </link>
  <joint name="leg_0_1_2" type="revolute">
    <parent link="leg_0_1"/>
    <child link="leg_0_2"/>
    <limit effort="30.0" lower="-0.78539816339" upper="0.78539816339" velocity="7.0"/>
    <origin rpy="0 0 0" xyz="0 0.06 0"/>
    <axis xyz="1 0 0"/>
    <dynamics damping="0.0"/>
  </joint>
  <link name="leg_0_2">
    <visual>
      <origin rpy="1.57079632679 0 0" xyz="0.01 0.0428496911663 0"/>
      <geometry>
        <cylinder length="0.0856993823327" radius="0.02"/>
      </geometry>
      <material name="Blue"/>
    </visual>
    <collision>
      <origin rpy="1.57079632679 0 0" xyz="0.01 0.0428496911663 0"/>
      <geometry>
        <box size="0.02 0.02 0.0856993823327"/>
      </geometry>
    </collision>
    <inertial>
      <!-- CENTER OF MASS -->
      <origin rpy="1.57079632679 0 0" xyz="0.01 0.0428496911663 0"/>
      <mass value="0.184"/>
      <!-- box inertia: 1/12*m(y^2+z^2), ... -->
      <inertia ixx="0.00011874722336" ixy="0" ixz="0" iyy="0.00011874722336" iyz="0" izz="1.22666666667e-05"/>
    </inertial>
  </link>
  <joint name="leg_0_2_3" type="revolute">
    <parent link="leg_0_2"/>
    <child link="leg_0_3"/>
    <limit effort="30.0" lower="-0.78539816339" upper="0.78539816339" velocity="7.0"/>
    <origin rpy="-1.57079632679 0 0" xyz="0 0.0856993823327 0"/>
    <axis xyz="-1 0 0"/>
    <dynamics damping="0.0"/>
  </joint>
  <link name="leg_0_3">
    <visual>
      <origin rpy="1.57079632679 0 0" xyz="0.0125 0.073885991801 0"/>
      <geometry>
        <cylinder length="0.147771983602" radius="0.025"/>
      </geometry>
      <material name="Red"/>
    </visual>
    <visual>
      <origin rpy="1.57079632679 0 0" xyz="0.0125 0.135271983602 0"/>
      <geometry>
        <sphere radius="0.025"/>
      </geometry>
      <material name="Red"/>
    </visual>
    <collision>
      <origin rpy="1.57079632679 0 0" xyz="0.0125 0.073885991801 0"/>
      <geometry>
        <box size="0.025 0.025 0.147771983602"/>
      </geometry>
    </collision>
    <collision>
      <origin rpy="1.57079632679 0 0" xyz="0.0125 0.135271983602 0"/>
      <geometry>
        <sphere radius="0.025"/>
      </geometry>
      <material name="Red"/>
    </collision>
    <inertial>
      <!-- CENTER OF MASS -->
      <origin rpy="1.57079632679 0 0" xyz="0.0125 0.073885991801 0"/>
      <mass value="0.04"/>
      <!-- box inertia: 1/12*m(y^2+z^2), ... -->
      <inertia ixx="7.48718637922e-05" ixy="0" ixz="0" iyy="7.48718637922e-05" iyz="0" izz="4.16666666667e-06"/>
    </inertial>
  </link>
  <joint name="body_leg_5" type="revolute">
    <parent link="base_link"/>
    <child link="leg_5_1"/>
    <limit effort="30.0" lower="-1.57079632679" upper="1.57079632679" velocity="7.0"/>
    <origin rpy="0 0 -0.3" xyz="-0.13 -0.04 0"/>
    <!-- <xacro:if value="${index == 5 or index == 4 or index == 3}">
                <axis xyz="0 0 1"/>
            </xacro:if>
            <xacro:if value="${index == 2 or index == 1 or index == 0}"> -->
    <axis xyz="0 0 1"/>
    <!-- </xacro:if> -->
    <dynamics damping="0.0"/>
  </joint>
  <link name="leg_5_1">
    <visual>
      <origin rpy="1.57079632679 0 0" xyz="0.01 -0.03 0"/>
      <geometry>
        <cylinder length="0.06" radius="0.02"/>
      </geometry>
      <material name="Red"/>
    </visual>
    <collision>
      <origin rpy="1.57079632679 0 0" xyz="0.01 -0.03 0"/>
      <geometry>
        <box size="0.02 0.02 0.06"/>
      </geometry>
    </collision>
    <inertial>
      <!-- CENTER OF MASS -->
      <origin rpy="1.57079632679 0 0" xyz="0.01 -0.03 0"/>
      <mass value="0.02"/>
      <!-- box inertia: 1/12*m(y^2+z^2), ... -->
      <inertia ixx="6.66666666667e-06" ixy="0" ixz="0" iyy="6.66666666667e-06" iyz="0" izz="1.33333333333e-06"/>
    </inertial>
  </link>
  <joint name="leg_5_1_2" type="revolute">
    <parent link="leg_5_1"/>
    <child link="leg_5_2"/>
    <limit effort="30.0" lower="-0.78539816339" upper="0.78539816339" velocity="7.0"/>
    <origin rpy="0 0 0" xyz="0 -0.06 0"/>
    <axis xyz="-1 0 0"/>
    <dynamics damping="0.0"/>
  </joint>
  <link name="leg_5_2">
    <visual>
      <origin rpy="1.57079632679 0 0" xyz="0.01 -0.0304606850262 0"/>
      <geometry>
        <cylinder length="0.0609213700523" radius="0.02"/>
      </geometry>
      <material name="Blue"/>
    </visual>
    <collision>
      <origin rpy="1.57079632679 0 0" xyz="0.01 -0.0304606850262 0"/>
      <geometry>
        <box size="0.02 0.02 0.0609213700523"/>
      </geometry>
    </collision>
    <inertial>
      <!-- CENTER OF MASS -->
      <origin rpy="1.57079632679 0 0" xyz="0.01 -0.0304606850262 0"/>
      <mass value="0.184"/>
      <!-- box inertia: 1/12*m(y^2+z^2), ... -->
      <inertia ixx="6.30416710454e-05" ixy="0" ixz="0" iyy="6.30416710454e-05" iyz="0" izz="1.22666666667e-05"/>
    </inertial>
  </link>
  <joint name="leg_5_2_3" type="revolute">
    <parent link="leg_5_2"/>
    <child link="leg_5_3"/>
    <limit effort="30.0" lower="-0.78539816339" upper="0.78539816339" velocity="7.0"/>
    <origin rpy="1.57079632679 0 0" xyz="0 -0.0609213700523 0"/>
    <axis xyz="1 0 0"/>
    <dynamics damping="0.0"/>
  </joint>
  <link name="leg_5_3">
    <visual>
      <origin rpy="1.57079632679 0 0" xyz="0.0125 -0.065363239586 0"/>
      <geometry>
        <cylinder length="0.130726479172" radius="0.025"/>
      </geometry>
      <material name="Red"/>
    </visual>
    <visual>
      <origin rpy="1.57079632679 0 0" xyz="0.0125 -0.118226479172 0"/>
      <geometry>
        <sphere radius="0.025"/>
      </geometry>
      <material name="Red"/>
    </visual>
    <collision>
      <origin rpy="1.57079632679 0 0" xyz="0.0125 -0.065363239586 0"/>
      <geometry>
        <box size="0.025 0.025 0.130726479172"/>
      </geometry>
    </collision>
    <collision>
      <origin rpy="1.57079632679 0 0" xyz="0.0125 -0.118226479172 0"/>
      <geometry>
        <sphere radius="0.025"/>
      </geometry>
      <material name="Red"/>
    </collision>
    <inertial>
      <!-- CENTER OF MASS -->
      <origin rpy="1.57079632679 0 0" xyz="0.0125 -0.065363239586 0"/>
      <mass value="0.04"/>
      <!-- box inertia: 1/12*m(y^2+z^2), ... -->
      <inertia ixx="5.9048041189e-05" ixy="0" ixz="0" iyy="5.9048041189e-05" iyz="0" izz="4.16666666667e-06"/>
    </inertial>
  </link>
  <joint name="body_leg_1" type="revolute">
    <parent link="base_link"/>
    <child link="leg_1_1"/>
    <limit effort="30.0" lower="-1.57079632679" upper="1.57079632679" velocity="7.0"/>
    <origin rpy="0 0 0" xyz="-0.01 0.08 0"/>
    <!-- <xacro:if value="${index == 5 or index == 4 or index == 3}">
                <axis xyz="0 0 1"/>
            </xacro:if>
            <xacro:if value="${index == 2 or index == 1 or index == 0}"> -->
    <axis xyz="0 0 1"/>
    <!-- </xacro:if> -->
    <dynamics damping="0.0"/>
  </joint>
  <link name="leg_1_1">
    <visual>
      <origin rpy="1.57079632679 0 0" xyz="0.01 0.03 0"/>
      <geometry>
        <cylinder length="0.06" radius="0.02"/>
      </geometry>
      <material name="Red"/>
    </visual>
    <collision>
      <origin rpy="1.57079632679 0 0" xyz="0.01 0.03 0"/>
      <geometry>
        <box size="0.02 0.02 0.06"/>
      </geometry>
    </collision>
    <inertial>
      <!-- CENTER OF MASS -->
      <origin rpy="1.57079632679 0 0" xyz="0.01 0.03 0"/>
      <mass value="0.02"/>
      <!-- box inertia: 1/12*m(y^2+z^2), ... -->
      <inertia ixx="6.66666666667e-06" ixy="0" ixz="0" iyy="6.66666666667e-06" iyz="0" izz="1.33333333333e-06"/>
    </inertial>
  </link>
  <joint name="leg_1_1_2" type="revolute">
    <parent link="leg_1_1"/>
    <child link="leg_1_2"/>
    <limit effort="30.0" lower="-0.78539816339" upper="0.78539816339" velocity="7.0"/>
    <origin rpy="0 0 0" xyz="0 0.06 0"/>
    <axis xyz="1 0 0"/>
    <dynamics damping="0.0"/>
  </joint>
  <link name="leg_1_2">
    <visual>
      <origin rpy="1.57079632679 0 0" xyz="0.01 0.050988208866 0"/>
      <geometry>
        <cylinder length="0.101976417732" radius="0.02"/>
      </geometry>
      <material name="Blue"/>
    </visual>
    <collision>
      <origin rpy="1.57079632679 0 0" xyz="0.01 0.050988208866 0"/>
      <geometry>
        <box size="0.02 0.02 0.101976417732"/>
      </geometry>
    </collision>
    <inertial>
      <!-- CENTER OF MASS -->
      <origin rpy="1.57079632679 0 0" xyz="0.01 0.050988208866 0"/>
      <mass value="0.184"/>
      <!-- box inertia: 1/12*m(y^2+z^2), ... -->
      <inertia ixx="0.000165587576526" ixy="0" ixz="0" iyy="0.000165587576526" iyz="0" izz="1.22666666667e-05"/>
    </inertial>
  </link>
  <joint name="leg_1_2_3" type="revolute">
    <parent link="leg_1_2"/>
    <child link="leg_1_3"/>
    <limit effort="30.0" lower="-0.78539816339" upper="0.78539816339" velocity="7.0"/>
    <origin rpy="-1.57079632679 0 0" xyz="0 0.101976417732 0"/>
    <axis xyz="-1 0 0"/>
    <dynamics damping="0.0"/>
  </joint>
  <link name="leg_1_3">
    <visual>
      <origin rpy="1.57079632679 0 0" xyz="0.0125 0.089585310325 0"/>
      <geometry>
        <cylinder length="0.17917062065" radius="0.025"/>
      </geometry>
      <material name="Red"/>
    </visual>
    <visual>
      <origin rpy="1.57079632679 0 0" xyz="0.0125 0.16667062065 0"/>
      <geometry>
        <sphere radius="0.025"/>
      </geometry>
      <material name="Red"/>
    </visual>
    <collision>
      <origin rpy="1.57079632679 0 0" xyz="0.0125 0.089585310325 0"/>
      <geometry>
        <box size="0.025 0.025 0.17917062065"/>
      </geometry>
    </collision>
    <collision>
      <origin rpy="1.57079632679 0 0" xyz="0.0125 0.16667062065 0"/>
      <geometry>
        <sphere radius="0.025"/>
      </geometry>
      <material name="Red"/>
    </collision>
    <inertial>
      <!-- CENTER OF MASS -->
      <origin rpy="1.57079632679 0 0" xyz="0.0125 0.089585310325 0"/>
      <mass value="0.04"/>
      <!-- box inertia: 1/12*m(y^2+z^2), ... -->
      <inertia ixx="0.000109090371014" ixy="0" ixz="0" iyy="0.000109090371014" iyz="0" izz="4.16666666667e-06"/>
    </inertial>
  </link>
  <joint name="body_leg_4" type="revolute">
    <parent link="base_link"/>
    <child link="leg_4_1"/>
    <limit effort="30.0" lower="-1.57079632679" upper="1.57079632679" velocity="7.0"/>
    <origin rpy="0 0 0" xyz="-0.01 -0.08 0"/>
    <!-- <xacro:if value="${index == 5 or index == 4 or index == 3}">
                <axis xyz="0 0 1"/>
            </xacro:if>
            <xacro:if value="${index == 2 or index == 1 or index == 0}"> -->
    <axis xyz="0 0 1"/>
    <!-- </xacro:if> -->
    <dynamics damping="0.0"/>
  </joint>
  <link name="leg_4_1">
    <visual>
      <origin rpy="1.57079632679 0 0" xyz="0.01 -0.03 0"/>
      <geometry>
        <cylinder length="0.06" radius="0.02"/>
      </geometry>
      <material name="Red"/>
    </visual>
    <collision>
      <origin rpy="1.57079632679 0 0" xyz="0.01 -0.03 0"/>
      <geometry>
        <box size="0.02 0.02 0.06"/>
      </geometry>
    </collision>
    <inertial>
      <!-- CENTER OF MASS -->
      <origin rpy="1.57079632679 0 0" xyz="0.01 -0.03 0"/>
      <mass value="0.02"/>
      <!-- box inertia: 1/12*m(y^2+z^2), ... -->
      <inertia ixx="6.66666666667e-06" ixy="0" ixz="0" iyy="6.66666666667e-06" iyz="0" izz="1.33333333333e-06"/>
    </inertial>
  </link>
  <joint name="leg_4_1_2" type="revolute">
    <parent link="leg_4_1"/>
    <child link="leg_4_2"/>
    <limit effort="30.0" lower="-0.78539816339" upper="0.78539816339" velocity="7.0"/>
    <origin rpy="0 0 0" xyz="0 -0.06 0"/>
    <axis xyz="-1 0 0"/>
    <dynamics damping="0.0"/>
  </joint>
  <link name="leg_4_2">
    <visual>
      <origin rpy="1.57079632679 0 0" xyz="0.01 -0.0598340898115 0"/>
      <geometry>
        <cylinder length="0.119668179623" radius="0.02"/>
      </geometry>
      <material name="Blue"/>
    </visual>
    <collision>
      <origin rpy="1.57079632679 0 0" xyz="0.01 -0.0598340898115 0"/>
      <geometry>
        <box size="0.02 0.02 0.119668179623"/>
      </geometry>
    </collision>
    <inertial>
      <!-- CENTER OF MASS -->
      <origin rpy="1.57079632679 0 0" xyz="0.01 -0.0598340898115 0"/>
      <mass value="0.184"/>
      <!-- box inertia: 1/12*m(y^2+z^2), ... -->
      <inertia ixx="0.000225713922619" ixy="0" ixz="0" iyy="0.000225713922619" iyz="0" izz="1.22666666667e-05"/>
    </inertial>
  </link>
  <joint name="leg_4_2_3" type="revolute">
    <parent link="leg_4_2"/>
    <child link="leg_4_3"/>
    <limit effort="30.0" lower="-0.78539816339" upper="0.78539816339" velocity="7.0"/>
    <origin rpy="1.57079632679 0 0" xyz="0 -0.119668179623 0"/>
    <axis xyz="1 0 0"/>
    <dynamics damping="0.0"/>
  </joint>
  <link name="leg_4_3">
    <visual>
      <origin rpy="1.57079632679 0 0" xyz="0.0125 -0.0611758986685 0"/>
      <geometry>
        <cylinder length="0.122351797337" radius="0.025"/>
      </geometry>
      <material name="Red"/>
    </visual>
    <visual>
      <origin rpy="1.57079632679 0 0" xyz="0.0125 -0.109851797337 0"/>
      <geometry>
        <sphere radius="0.025"/>
      </geometry>
      <material name="Red"/>
    </visual>
    <collision>
      <origin rpy="1.57079632679 0 0" xyz="0.0125 -0.0611758986685 0"/>
      <geometry>
        <box size="0.025 0.025 0.122351797337"/>
      </geometry>
    </collision>
    <collision>
      <origin rpy="1.57079632679 0 0" xyz="0.0125 -0.109851797337 0"/>
      <geometry>
        <sphere radius="0.025"/>
      </geometry>
      <material name="Red"/>
    </collision>
    <inertial>
      <!-- CENTER OF MASS -->
      <origin rpy="1.57079632679 0 0" xyz="0.0125 -0.0611758986685 0"/>
      <mass value="0.04"/>
      <!-- box inertia: 1/12*m(y^2+z^2), ... -->
      <inertia ixx="5.19832077053e-05" ixy="0" ixz="0" iyy="5.19832077053e-05" iyz="0" izz="4.16666666667e-06"/>
    </inertial>
  </link>
  <!-- END OF LEG LINKS/JOINTS -->
</robot>
